Workbook

Sheet Base
A1: Nº | B1: N° Operación CMF | C1: Rut | D1: RUT | E1: DV | F1: Apellido paterno | G1: Apellido materno | H1: Nombres | I1: Género | J1: Segmento | K1: Pie | L1: Precio venta propiedad | M1: Subsidio | N1: Valor de tasación | O1: Tasa anual de emisión | P1: Tasa mensual de emisión | Q1: Plazo en meses | R1: Meses de gracia | S1: LTV | T1: Monto otorgado (UF) | U1: Valor cuota (UF) | V1: Valor última cuota (UF) | W1: Spread | X1: Tasa anual de endoso | Y1: Tasa mensual de endoso | Z1: Fecha de suscripción | AA1: Período primer aporte | AB1: Fecha de endoso | AC1: Fecha primer aporte a endosar | AD1: Fecha último aporte | AE1: Número de cuotas a endosar | AF1: VAN fecha endoso | AG1: Dirección | AH1: Comuna | AI1: Ciudad | AJ1: Region | AK1: Notaría | AL1: Dividendo/ Renta | AM1: Carga Financiera
A2: 1 | B2: 202403250103A033 | C2: 18803188-9 | D2: =LEFT(C2,LEN(C2)-2) -> 18803188 | E2: =RIGHT(C2,1) -> 9 | F2: Diaz | G2: Zuñiga | H2: Joel Alejandro | I2: Masculino | J2: Subsidio | K2: 605 | L2: 2200 | M2: 525 | N2: 2325 | O2: 0.0753 | P2: 0.0060683124 | Q2: 300 | R2: 5 | S2: 0.725 | T2: 1595 | U2: 11.98802 | V2: 11.919435 | W2: -0.004 | X2: 0.0713 | Y2: 0.0057559073 | Z2: 45376 | AA2: 45575 | AB2: 45379 | AC2: 45575 | AD2: 54523 | AE2: 295 | AF2: 1647.6019 | AG2: Calle 8 Sur Poniente 351,casa 351 | AH2: Los Ángeles | AI2: Biobío | AJ2: Región del Biobío | AK2: María Antonieta Carrillo Flores | AL2: 0.25914525 | AM2: 0.32831376 | AN2: 682 | AO2: OK | AP2: Firmada
A3: =A2+1 -> 2 | B3: 202403260104A033 | C3: 16265854-9 | D3: =LEFT(C3,LEN(C3)-2) -> 16265854 | E3: =RIGHT(C3,1) -> 9 | F3: Hultazo | G3: Novoa | H3: Daniela Del Carmen | I3: Femenino | J3: Subsidio | K3: 750 | L3: 2200 | M3: 550 | N3: 2560 | O3: 0.0753 | P3: 0.0060683124 | Q3: 360 | R3: 5 | S3: 0.67294545 | T3: 1480.48 | U3: 10.483279 | V3: 10.761609 | W3: -0.004 | X3: 0.0713 | Y3: 0.0057559073 | Z3: 45377 | AA3: 45575 | AB3: 45379 | AC3: 45575 | AD3: 56349 | AE3: 355 | AF3: 1534.7211 | AG3: ADRIANA GARCIA IBAÑEZ 2030, Edificio G,departamento 303 | AH3: San Javier | AI3: Linares | AJ3: Región del Maule | AK3: Gabriel Guerrero González | AL3: 0.17374483 | AM3: 0.46168658 | AN3: 1136 | AO3: OK | AP3: Firmada
A4: =A3+1 -> 3 | B4: 202403250105A033 | C4: 24585394-7 | D4: =LEFT(C4,LEN(C4)-2) -> 24585394 | E4: =RIGHT(C4,1) -> 7 | F4: Salazar | G4: Carvajal | H4: Nedier Graciela | I4: Femenino | J4: Subsidio | K4: 536.04 | L4: 1400 | M4: 450 | N4: 1400 | O4: 0.0753 | P4: 0.0060683124 | Q4: 312 | R4: 5 | S4: 0.61711429 | T4: 863.96 | U4: 6.402808 | V4: 6.596335 | W4: -0.004 | X4: 0.0713 | Y4: 0.0057559073 | Z4: 45376 | AA4: 45575 | AB4: 45379 | AC4: 45575 | AD4: 54888 | AE4: 307 | AF4: 892.6874 | AG4: Camino La Vara 02600, Torre 1,departamento 406 | AH4: San Bernardo | AI4: Maipo | AJ4: Región Metropolitana de Santiago | AK4: Pablo Martínez Loaiza | AL4: 0.34565539 | AM4: 0.54730716 | AN4: 5481 | AO4: OK | AP4: Firmada
A5: =A4+1 -> 4 | B5: 202403260108A033 | C5: 26537872-2 | D5: =LEFT(C5,LEN(C5)-2) -> 26537872 | E5: =RIGHT(C5,1) -> 2 | F5: Vasquez | G5: Sanchez | H5: Bertha Ramona | I5: Femenino | J5: Subsidio | K5: 583 | L5: 2300 | M5: 475 | N5: 2300 | O5: 0.0753 | P5: 0.0060683124 | Q5: 264 | R5: 5 | S5: 0.74652174 | T5: 1717 | U5: 13.571168 | V5: 13.454412 | W5: -0.004 | X5: 0.0713 | Y5: 0.0057559073 | Z5: 45377 | AA5: 45575 | AB5: 45379 | AC5: 45575 | AD5: 53427 | AE5: 259 | AF5: 1768.2353 | AG5: Calle 38 Oriente 350, Torre 8,departamento 2804 | AH5: Talca | AI5: Talca | AJ5: Región del Maule | AK5: Teodoro Durán Palma | AL5: 0.36411949 | AM5: 0.41283351 | AN5: 1753 | AO5: OK | AP5: Firmada
A6: =A5+1 -> 5 | B6: 202403250112A033 | C6: 18188333-2 | D6: =LEFT(C6,LEN(C6)-2) -> 18188333 | E6: =RIGHT(C6,1) -> 2 | F6: Huenchul | G6: Colihuinca | H6: César Antonio | I6: Masculino | J6: Subsidio | K6: 518.4 | L6: 2070 | M6: 375 | N6: 2400 | O6: 0.0753 | P6: 0.0060683124 | Q6: 360 | R6: 5 | S6: 0.74956522 | T6: 1551.6 | U6: 10.98688 | V6: 11.27858 | W6: -0.004 | X6: 0.0713 | Y6: 0.0057559073 | Z6: 45376 | AA6: 45575 | AB6: 45379 | AC6: 45575 | AD6: 56349 | AE6: 355 | AF6: 1609.4065 | AG6: Camino La Vara 02600, TORRE 2,departamento 412 | AH6: San Bernardo | AI6: Maipo | AJ6: Región Metropolitana de Santiago | AK6: Pablo Martínez Loaiza | AL6: 0.40025143 | AM6: 0.42269568 | AN6: 5560 | AO6: OK | AP6: Firmada
A7: =A6+1 -> 6 | B7: 202403260115A033 | C7: 18250306-1 | D7: =LEFT(C7,LEN(C7)-2) -> 18250306 | E7: =RIGHT(C7,1) -> 1 | F7: Rojas | G7: Diaz | H7: Claudio Sebastian | I7: Masculino | J7: Subsidio | K7: 1035.77 | L7: 2700 | M7: 700 | N7: 2700 | O7: 0.0753 | P7: 0.0060683124 | Q7: 300 | R7: 5 | S7: 0.61638148 | T7: 1664.23 | U7: 12.508353 | V7: 12.436791 | W7: -0.004 | X7: 0.0713 | Y7: 0.0057559073 | Z7: 45377 | AA7: 45575 | AB7: 45379 | AC7: 45575 | AD7: 54523 | AE7: 295 | AF7: 1719.0581 | AG7: Los Libertadores 4733, Edificio F,departamento 106 | AH7: Cerrillos | AI7: Santiago | AJ7: Región Metropolitana de Santiago | AK7: Pablo Martínez Loaiza | AL7: 0.16448389 | AM7: 0.37966625 | AN7: 5566 | AO7: OK | AP7: Firmada
A8: =A7+1 -> 7 | B8: 202403260117A033 | C8: 17747816-4 | D8: =LEFT(C8,LEN(C8)-2) -> 17747816 | E8: =RIGHT(C8,1) -> 4 | F8: Lagos | G8: Muñoz | H8: Pablo Daniel | I8: Masculino | J8: Subsidio | K8: 650 | L8: 2250 | M8: 550 | N8: 2460 | O8: 0.0753 | P8: 0.0060683124 | Q8: 360 | R8: 5 | S8: 0.72487778 | T8: 1630.975 | U8: 11.548934 | V8: 11.855557 | W8: -0.004 | X8: 0.0713 | Y8: 0.0057559073 | Z8: 45377 | AA8: 45575 | AB8: 45379 | AC8: 45575 | AD8: 56349 | AE8: 355 | AF8: 1691.4151 | AG8: ADRIANA GARCIA IBAÑEZ 2030, Torre B,departamento 401 | AH8: San Javier | AI8: Linares | AJ8: Región del Maule | AK8: Gabriel Guerrero González | AL8: 0.33391403 | AM8: 0.49056281 | AN8: 1134 | AO8: OK | AP8: Firmada
A9: =A8+1 -> 8 | B9: 202403220119A033 | C9: 17137105-8 | D9: =LEFT(C9,LEN(C9)-2) -> 17137105 | E9: =RIGHT(C9,1) -> 8 | F9: Jaña | G9: Avila | H9: Francisco Javier | I9: Masculino | J9: Subsidio | K9: 618.63 | L9: 1400 | M9: 400 | N9: 1410 | O9: 0.0753 | P9: 0.0060683124 | Q9: 360 | R9: 5 | S9: 0.55812143 | T9: 781.37 | U9: 5.532881 | V9: 5.679779 | W9: -0.004 | X9: 0.0713 | Y9: 0.0057559073 | Z9: 45373 | AA9: 45575 | AB9: 45379 | AC9: 45575 | AD9: 56349 | AE9: 355 | AF9: 809.82925 | AG9: Av. El Valle 199, Torre B,departamento 101 | AH9: Rancagua | AI9: Cachapoal | AJ9: Región del Libertador General Bernardo O'Higgins | AK9: Gerardo Carvallo Castillo | AL9: 0.38354014 | AM9: 0.50324471 | AN9: 789 | AO9: OK | AP9: Firmada
A10: =A9+1 -> 9 | B10: 202403260120A033 | C10: 16995140-3 | D10: =LEFT(C10,LEN(C10)-2) -> 16995140 | E10: =RIGHT(C10,1) -> 3 | F10: Oñate | G10: Muñoz | H10: Pablo Enrique | I10: Masculino | J10: Subsidio | K10: 640 | L10: 1400 | M10: 600 | N10: 1600 | O10: 0.0753 | P10: 0.0060683124 | Q10: 216 | R10: 5 | S10: 0.54285714 | T10: 760 | U10: 6.593 | V10: 6.50864 | W10: -0.004 | X10: 0.0713 | Y10: 0.0057559073 | Z10: 45377 | AA10: 45575 | AB10: 45379 | AC10: 45575 | AD10: 51966 | AE10: 211 | AF10: 779.0959 | AG10: PROFESOR PASCUAL PEREIRA 1324,casa 1324 | AH10: Nacimiento | AI10: Biobío | AJ10: Región del Biobío | AK10: Cristian Camilla Sandoval | AL10: 0.1583457 | AM10: 0.40708554 | AN10: 851 | AO10: OK | AP10: Firmada
A11: =A10+1 -> 10 | B11: 202403250121A033 | C11: 18645373-5 | D11: =LEFT(C11,LEN(C11)-2) -> 18645373 | E11: =RIGHT(C11,1) -> 5 | F11: Aranguiz | G11: Arevalo | H11: Macarena Andrea Del Carmen | I11: Femenino | J11: Subsidio | K11: 418 | L11: 2090 | M11: 325 | N11: 2200 | O11: 0.0753 | P11: 0.0060683124 | Q11: 360 | R11: 5 | S11: 0.8 | T11: 1672 | U11: 11.839432 | V11: 12.153768 | W11: -0.004 | X11: 0.0713 | Y11: 0.0057559073 | Z11: 45376 | AA11: 45575 | AB11: 45379 | AC11: 45575 | AD11: 56349 | AE11: 355 | AF11: 1733.8826 | AG11: Av El Valle 199, Torre B,departamento 407 | AH11: Rancagua | AI11: Cachapoal | AJ11: Región del Libertador General Bernardo O'Higgins | AK11: Gerardo Carvallo Castillo | AL11: 0.24855131 | AM11: 0.39683384 | AN11: 808 | AO11: OK | AP11: Firmada
A12: =A11+1 -> 11 | B12: 202403250123A033 | C12: 16681463-4 | D12: =LEFT(C12,LEN(C12)-2) -> 16681463 | E12: =RIGHT(C12,1) -> 4 | F12: Moraga | G12: Carrasco | H12: Jenny Alejandra | I12: Femenino | J12: Subsidio | K12: 522.22 | L12: 1400 | M12: 450 | N12: 1400 | O12: 0.0753 | P12: 0.0060683124 | Q12: 240 | R12: 5 | S12: 0.62698571 | T12: 877.78 | U12: 7.236418 | V12: 7.068762 | W12: -0.004 | X12: 0.0713 | Y12: 0.0057559073 | Z12: 45376 | AA12: 45575 | AB12: 45379 | AC12: 45575 | AD12: 52697 | AE12: 235 | AF12: 902.65751 | AG12: PASAJE DEMOFILA TORREALBA (PROFESORA) 1744,casa 1744 | AH12: Rengo | AI12: Cachapoal | AJ12: Región del Libertador General Bernardo O'Higgins | AK12: Andrés Falcón Valencia | AL12: 0.27580802 | AM12: 0.28908034 | AN12: N/A | AO12: OK | AP12: Firmada
A13: =A12+1 -> 12 | B13: 202403250125A033 | C13: 24243822-1 | D13: =LEFT(C13,LEN(C13)-2) -> 24243822 | E13: =RIGHT(C13,1) -> 1 | F13: Pozo | G13: Salvatierra | H13: Eufronia | I13: Femenino | J13: Subsidio | K13: 933.25 | L13: 1700 | M13: 737.5 | N13: 1700 | O13: 0.0753 | P13: 0.0060683124 | Q13: 204 | R13: 5 | S13: 0.45102941 | T13: 766.75 | U13: 6.850911 | V13: 6.893849 | W13: -0.004 | X13: 0.0713 | Y13: 0.0057559073 | Z13: 45376 | AA13: 45575 | AB13: 45379 | AC13: 45575 | AD13: 51601 | AE13: 199 | AF13: 785.37074 | AG13: Los Libertadores 4733, Edificio F,departamento 808 | AH13: Cerrillos | AI13: Santiago | AJ13: Región Metropolitana de Santiago | AK13: Pablo Martínez Loaiza | AL13: 0.41766992 | AM13: 0.44378192 | AN13: 5557 | AO13: OK | AP13: Firmada
A14: =A13+1 -> 13 | B14: 202403270128A033 | C14: 10745032-7 | D14: =LEFT(C14,LEN(C14)-2) -> 10745032 | E14: =RIGHT(C14,1) -> 7 | F14: Herrera | G14: Labarca | H14: Ester Lorena | I14: Femenino | J14: Subsidio | K14: 903.54 | L14: 1600 | M14: 675 | N14: 1600 | O14: 0.0753 | P14: 0.0060683124 | Q14: 240 | R14: 5 | S14: 0.448725 | T14: 717.96 | U14: 5.918862 | V14: 5.781732 | W14: -0.004 | X14: 0.0713 | Y14: 0.0057559073 | Z14: 45378 | AA14: 45575 | AB14: 45379 | AC14: 45575 | AD14: 52697 | AE14: 235 | AF14: 738.08434 | AG14: EMMA GOLDMAN 3456,casa 3456 | AH14: Coquimbo | AI14: Elqui | AJ14: Región de Coquimbo | AK14: Juan Carlos Maturana | AL14: 0.24192368 | AM14: 0.28928929 | AN14: N/A | AO14: OK | AP14: Firmada
A15: =A14+1 -> 14 | B15: 202403250129A033 | C15: 18429503-2 | D15: =LEFT(C15,LEN(C15)-2) -> 18429503 | E15: =RIGHT(C15,1) -> 2 | F15: Daza | G15: Contreras | H15: Jocelyn Magdalena | I15: Femenino | J15: Subsidio | K15: 505 | L15: 2150 | M15: 425 | N15: 2150 | O15: 0.0753 | P15: 0.0060683124 | Q15: 360 | R15: 5 | S15: 0.76511628 | T15: 1645 | U15: 11.648245 | V15: 11.957505 | W15: -0.004 | X15: 0.0713 | Y15: 0.0057559073 | Z15: 45376 | AA15: 45575 | AB15: 45379 | AC15: 45575 | AD15: 56349 | AE15: 355 | AF15: 1706.059 | AG15: Camino Las Rosas 518, Edificio 12,departamento 52 | AH15: Chillán | AI15: Diguillín | AJ15: Región de Ñuble | AK15: Luis Álvarez Diaz | AL15: 0.28845392 | AM15: 0.43027696 | AN15: 1233 | AO15: OK | AP15: Firmada
A16: =A15+1 -> 15 | B16: 202403260131A033 | C16: 16415014-3 | D16: =LEFT(C16,LEN(C16)-2) -> 16415014 | E16: =RIGHT(C16,1) -> 3 | F16: Carrasco | G16: Barrientos | H16: Cesar Antonio | I16: Masculino | J16: Subsidio | K16: 750 | L16: 2600 | M16: 600 | N16: 2600 | O16: 0.0753 | P16: 0.0060683124 | Q16: 360 | R16: 5 | S16: 0.71153846 | T16: 1850 | U16: 13.09985 | V16: 13.44765 | W16: -0.004 | X16: 0.0713 | Y16: 0.0057559073 | Z16: 45377 | AA16: 45575 | AB16: 45379 | AC16: 45575 | AD16: 56349 | AE16: 355 | AF16: 1918.4013 | AG16: STELLA DIAZ VARIN 1901,departamento 1901 | AH16: Coquimbo | AI16: Elqui | AJ16: Región de Coquimbo | AK16: Juan Carlos Maturana | AL16: 0.37495021 | AM16: 0.43965438 | AN16: 638 | AO16: OK | AP16: Firmada
A17: =A16+1 -> 16 | B17: 202403250132A033 | C17: 19796943-1 | D17: =LEFT(C17,LEN(C17)-2) -> 19796943 | E17: =RIGHT(C17,1) -> 1 | F17: Yañez | G17: Gallardo | H17: Angelica Isabel | I17: Femenino | J17: Subsidio | K17: 505 | L17: 2150 | M17: 425 | N17: 2150 | O17: 0.0753 | P17: 0.0060683124 | Q17: 360 | R17: 5 | S17: 0.76511628 | T17: 1645 | U17: 11.648245 | V17: 11.957505 | W17: -0.004 | X17: 0.0713 | Y17: 0.0057559073 | Z17: 45376 | AA17: 45575 | AB17: 45379 | AC17: 45575 | AD17: 56349 | AE17: 355 | AF17: 1706.059 | AG17: Camino Las Rosas 518, Edificio 14,departamento 54 | AH17: Chillán | AI17: Diguillín | AJ17: Región de Ñuble | AK17: Luis Álvarez Diaz | AL17: 0.24543004 | AM17: 0.30375181 | AN17: 1236 | AO17: OK | AP17: Firmada
A18: =A17+1 -> 17 | B18: 202403260133A033 | C18: 18475742-7 | D18: =LEFT(C18,LEN(C18)-2) -> 18475742 | E18: =RIGHT(C18,1) -> 7 | F18: Torres | G18: Romero | H18: Evelyn Andrea | I18: Masculino | J18: Subsidio | K18: 730 | L18: 2250 | M18: 550 | N18: 2540 | O18: 0.0753 | P18: 0.0060683124 | Q18: 360 | R18: 5 | S18: 0.68932222 | T18: 1550.975 | U18: 10.982454 | V18: 11.274037 | W18: -0.004 | X18: 0.0713 | Y18: 0.0057559073 | Z18: 45377 | AA18: 45575 | AB18: 45379 | AC18: 45575 | AD18: 56349 | AE18: 355 | AF18: 1607.9421 | AG18: Calle Adriana García Ibáñez 2030, Torre F,departamento 202 | AH18: San Javier | AI18: Linares | AJ18: Región del Maule | AK18: Gabriel Guerrero González | AL18: 0.23529819 | AM18: 0.40352778 | AN18: 1135 | AO18: OK | AP18: Firmada
A19: =A18+1 -> 18 | B19: 202403250134A033 | C19: 14204102-2 | D19: =LEFT(C19,LEN(C19)-2) -> 14204102 | E19: =RIGHT(C19,1) -> 2 | F19: Nuñez | G19: Brito | H19: Fernanda Angelica | I19: Femenino | J19: Subsidio | K19: 487.6 | L19: 1400 | M19: 400 | N19: 1410 | O19: 0.0753 | P19: 0.0060683124 | Q19: 288 | R19: 5 | S19: 0.65171429 | T19: 912.4 | U19: 6.963437 | V19: 6.857598 | W19: -0.004 | X19: 0.0713 | Y19: 0.0057559073 | Z19: 45376 | AA19: 45575 | AB19: 45379 | AC19: 45575 | AD19: 54158 | AE19: 283 | AF19: 941.02322 | AG19: Avenida El Valle 199, Torre C,departamento 701 | AH19: Rancagua | AI19: Cachapoal | AJ19: Región del Libertador General Bernardo O'Higgins | AK19: Gerardo Carvallo Castillo | AL19: 0.26594348 | AM19: 0.38932645 | AN19: 802 | AO19: OK | AP19: Firmada
A20: =A19+1 -> 19 | B20: 202403250135A033 | C20: 13219684-2 | D20: =LEFT(C20,LEN(C20)-2) -> 13219684 | E20: =RIGHT(C20,1) -> 2 | F20: Cardenas | G20: Mardones | H20: Katherine Magdalena | I20: Femenino | J20: Subsidio | K20: 414 | L20: 2070 | M20: 325 | N20: 2200 | O20: 0.0753 | P20: 0.0060683124 | Q20: 360 | R20: 5 | S20: 0.8 | T20: 1656 | U20: 11.726136 | V20: 12.037464 | W20: -0.004 | X20: 0.0713 | Y20: 0.0057559073 | Z20: 45376 | AA20: 45575 | AB20: 45379 | AC20: 45575 | AD20: 56349 | AE20: 355 | AF20: 1717.7742 | AG20: Avenida El Valle 199, Torre A,departamento 303 | AH20: Rancagua | AI20: Cachapoal | AJ20: Región del Libertador General Bernardo O'Higgins | AK20: Gerardo Carvallo Castillo | AL20: 0.18073504 | AM20: 0.27390952 | AN20: 800 | AO20: OK | AP20: Firmada
A21: =A20+1 -> 20 | B21: 202403250138A033 | C21: 27097423-6 | D21: =LEFT(C21,LEN(C21)-2) -> 27097423 | E21: =RIGHT(C21,1) -> 6 | F21: Rivera | G21: De Carreño | H21: Rosmery Josefina | I21: Femenino | J21: Subsidio | K21: 940 | L21: 2800 | M21: 700 | N21: 2800 | O21: 0.0753 | P21: 0.0060683124 | Q21: 360 | R21: 5 | S21: 0.66428571 | T21: 1860 | U21: 13.17 | V21: 13.52 | W21: -0.004 | X21: 0.0713 | Y21: 0.0057559073 | Z21: 45376 | AA21: 45575 | AB21: 45379 | AC21: 45575 | AD21: 56349 | AE21: 355 | AF21: 1928.6521 | AG21: Los Libertadores 4733, Edificio H | AH21: Cerrillos | AI21: Santiago | AJ21: Región Metropolitana de Santiago | AK21: Pablo Martínez Loaiza | AL21: 0.1773358 | AM21: 0.21092959 | AN21: 5492 | AO21: OK | AP21: Firmada

Sheet Valo FX
V1: valor Creditú
I2: Monto Crédito + Cap (UF) | P2: Tasa endoso | Q2: Fecha 1er Aporte a endosar | R2: Fecha Last Aporte | S2: Fecha Corte | U2: VPN | V2: Tasa mensual de endoso | X2: Tasacion | Y2: Precio Venta/Tasación | Z2: Tasa Endoso | AA2: Monto Dividendo | AB2: Dividendo/ Renta | AC2: Carga Financiera/ Renta
A3: Nº | B3: N° Operación | C3: Apellido paterno | D3: Apellido materno | E3: Nombres | F3: Rut | G3: DV | H3: Fecha de emisión | J3: Subsidio | K3: Pie | L3: Valor Vivienda | M3: Morosidad | N3: Nº Cuotas | O3: Primera cuota a endosar | T3: 45392 | U3: 45379 | W3: Saldo insoluto Teórico | AD3: Dirección de la Propiedad | AE3: Codigo Comuna | AF3: Comuna
A4: =+Base!A2 -> 1 | B4: =+Base!B2 -> 202403250103A033 | C4: =+Base!F2 -> Diaz | D4: =+Base!G2 -> Zuñiga | E4: =+Base!H2 -> Joel Alejandro | F4: =+Base!D2 -> 18803188 | G4: =+Base!E2 -> 9 | H4: =+Base!Z2 -> 45376 | I4: =+Base!T2 -> 1595 | J4: =+Base!M2 -> 525 | K4: =+L4-J4-I4 -> 80 | L4: =+Base!L2 -> 2200 | M4: 0 | N4: =+Base!Q2 -> 300 | O4: =+Base!R2+1 -> 6 | P4: =+XIRR('Tabla desarrollo FX'!B3:MY3,'Tabla desarrollo FX'!$B$1:$MY$1) -> 0.070972547 | Q4: =+Base!AA2 -> 45575 | R4: =+Base!AD2 -> 54523 | S4: =$T$3 -> 45392 | T4: =+NPV(V4,'Tabla desarrollo FX'!D3:MY3) -> 1651.534 | U4: =+Base!AF2 -> 1647.6019 | V4: =+Base!Y2 -> 0.0057559073 | W4: =+Base!T2 -> 1595 | X4: =+Base!N2 -> 2325 | Y4: =+U4/X4 -> 0.70864598 | Z4: =+P4-Base!O2 -> -0.0043274531 | AA4: =+Base!U2 -> 11.98802 | AB4: =+Base!AL2*100 -> 25.914525 | AC4: =+Base!AM2*100 -> 32.831376 | AD4: =+Base!AG2 -> Calle 8 Sur Poniente 351,casa 351 | AE4: =+VLOOKUP(AF4,Comuna!A:B,2,0) -> #N/A | AF4: =+Base!AI2 -> Biobío
A5: =+Base!A3 -> 2 | B5: =+Base!B3 -> 202403260104A033 | C5: =+Base!F3 -> Hultazo | D5: =+Base!G3 -> Novoa | E5: =+Base!H3 -> Daniela Del Carmen | F5: =+Base!D3 -> 16265854 | G5: =+Base!E3 -> 9 | H5: =+Base!Z3 -> 45377 | I5: =+Base!T3 -> 1480.48 | J5: =+Base!M3 -> 550 | K5: =+L5-J5-I5 -> 169.52 | L5: =+Base!L3 -> 2200 | M5: 1 | N5: =+Base!Q3 -> 360 | O5: =+Base!R3+1 -> 6 | P5: =+XIRR('Tabla desarrollo FX'!B4:MY4,'Tabla desarrollo FX'!$B$1:$MY$1) -> 0.071001557 | Q5: =+Base!AA3 -> 45575 | R5: =+Base!AD3 -> 56349 | S5: =$T$3 -> 45392 | T5: =+NPV(V5,'Tabla desarrollo FX'!D4:MY4) -> 1539.1184 | U5: =+Base!AF3 -> 1534.7211 | V5: =+Base!Y3 -> 0.0057559073 | W5: =+Base!T3 -> 1480.48 | X5: =+Base!N3 -> 2560 | Y5: =+U5/X5 -> 0.59950042 | Z5: =+P5-Base!O3 -> -0.0042984435 | AA5: =+Base!U3 -> 10.483279 | AB5: =+Base!AL3*100 -> 17.374483 | AC5: =+Base!AM3*100 -> 46.168658 | AD5: =+Base!AG3 -> ADRIANA GARCIA IBAÑEZ 2030, Edificio G,departamento 303 | AE5: =+VLOOKUP(AF5,Comuna!A:B,2,0) -> 7401 | AF5: =+Base!AI3 -> Linares
A6: =+Base!A4 -> 3 | B6: =+Base!B4 -> 202403250105A033 | C6: =+Base!F4 -> Salazar | D6: =+Base!G4 -> Carvajal | E6: =+Base!H4 -> Nedier Graciela | F6: =+Base!D4 -> 24585394 | G6: =+Base!E4 -> 7 | H6: =+Base!Z4 -> 45376 | I6: =+Base!T4 -> 863.96 | J6: =+Base!M4 -> 450 | K6: =+L6-J6-I6 -> 86.04 | L6: =+Base!L4 -> 1400 | M6: 2 | N6: =+Base!Q4 -> 312 | O6: =+Base!R4+1 -> 6 | P6: =+XIRR('Tabla desarrollo FX'!B5:MY5,'Tabla desarrollo FX'!$B$1:$MY$1) -> 0.070979336 | Q6: =+Base!AA4 -> 45575 | R6: =+Base!AD4 -> 54888 | S6: =$T$3 -> 45392 | T6: =+NPV(V6,'Tabla desarrollo FX'!D5:MY5) -> 895.357 | U6: =+Base!AF4 -> 892.6874 | V6: =+Base!Y4 -> 0.0057559073 | W6: =+Base!T4 -> 863.96 | X6: =+Base!N4 -> 1400 | Y6: =+U6/X6 -> 0.63763386 | Z6: =+P6-Base!O4 -> -0.0043206641 | AA6: =+Base!U4 -> 6.402808 | AB6: =+Base!AL4*100 -> 34.565539 | AC6: =+Base!AM4*100 -> 54.730716 | AD6: =+Base!AG4 -> Camino La Vara 02600, Torre 1,departamento 406 | AE6: =+VLOOKUP(AF6,Comuna!A:B,2,0) -> #N/A | AF6: =+Base!AI4 -> Maipo
A7: =+Base!A5 -> 4 | B7: =+Base!B5 -> 202403260108A033 | C7: =+Base!F5 -> Vasquez | D7: =+Base!G5 -> Sanchez | E7: =+Base!H5 -> Bertha Ramona | F7: =+Base!D5 -> 26537872 | G7: =+Base!E5 -> 2 | H7: =+Base!Z5 -> 45377 | I7: =+Base!T5 -> 1717 | J7: =+Base!M5 -> 475 | K7: =+L7-J7-I7 -> 108 | L7: =+Base!L5 -> 2300 | M7: 3 | N7: =+Base!Q5 -> 264 | O7: =+Base!R5+1 -> 6 | P7: =+XIRR('Tabla desarrollo FX'!B6:MY6,'Tabla desarrollo FX'!$B$1:$MY$1) -> 0.070948073 | Q7: =+Base!AA5 -> 45575 | R7: =+Base!AD5 -> 53427 | S7: =$T$3 -> 45392 | T7: =+NPV(V7,'Tabla desarrollo FX'!D6:MY6) -> 1772.9012 | U7: =+Base!AF5 -> 1768.2353 | V7: =+Base!Y5 -> 0.0057559073 | W7: =+Base!T5 -> 1717 | X7: =+Base!N5 -> 2300 | Y7: =+U7/X7 -> 0.76879796 | Z7: =+P7-Base!O5 -> -0.0043519267 | AA7: =+Base!U5 -> 13.571168 | AB7: =+Base!AL5*100 -> 36.411949 | AC7: =+Base!AM5*100 -> 41.283351 | AD7: =+Base!AG5 -> Calle 38 Oriente 350, Torre 8,departamento 2804 | AE7: =+VLOOKUP(AF7,Comuna!A:B,2,0) -> 7101 | AF7: =+Base!AI5 -> Talca
A8: =+Base!A6 -> 5 | B8: =+Base!B6 -> 202403250112A033 | C8: =+Base!F6 -> Huenchul | D8: =+Base!G6 -> Colihuinca | E8: =+Base!H6 -> César Antonio | F8: =+Base!D6 -> 18188333 | G8: =+Base!E6 -> 2 | H8: =+Base!Z6 -> 45376 | I8: =+Base!T6 -> 1551.6 | J8: =+Base!M6 -> 375 | K8: =+L8-J8-I8 -> 143.4 | L8: =+Base!L6 -> 2070 | M8: 4 | N8: =+Base!Q6 -> 360 | O8: =+Base!R6+1 -> 6 | P8: =+XIRR('Tabla desarrollo FX'!B7:MY7,'Tabla desarrollo FX'!$B$1:$MY$1) -> 0.071001557 | Q8: =+Base!AA6 -> 45575 | R8: =+Base!AD6 -> 56349 | S8: =$T$3 -> 45392 | T8: =+NPV(V8,'Tabla desarrollo FX'!D7:MY7) -> 1613.0553 | U8: =+Base!AF6 -> 1609.4065 | V8: =+Base!Y6 -> 0.0057559073 | W8: =+Base!T6 -> 1551.6 | X8: =+Base!N6 -> 2400 | Y8: =+U8/X8 -> 0.67058603 | Z8: =+P8-Base!O6 -> -0.0042984435 | AA8: =+Base!U6 -> 10.98688 | AB8: =+Base!AL6*100 -> 40.025143 | AC8: =+Base!AM6*100 -> 42.269568 | AD8: =+Base!AG6 -> Camino La Vara 02600, TORRE 2,departamento 412 | AE8: =+VLOOKUP(AF8,Comuna!A:B,2,0) -> #N/A | AF8: =+Base!AI6 -> Maipo
A9: =+Base!A7 -> 6 | B9: =+Base!B7 -> 202403260115A033 | C9: =+Base!F7 -> Rojas | D9: =+Base!G7 -> Diaz | E9: =+Base!H7 -> Claudio Sebastian | F9: =+Base!D7 -> 18250306 | G9: =+Base!E7 -> 1 | H9: =+Base!Z7 -> 45377 | I9: =+Base!T7 -> 1664.23 | J9: =+Base!M7 -> 700 | K9: =+L9-J9-I9 -> 335.77 | L9: =+Base!L7 -> 2700 | M9: 5 | N9: =+Base!Q7 -> 300 | O9: =+Base!R7+1 -> 6 | P9: =+XIRR('Tabla desarrollo FX'!B8:MY8,'Tabla desarrollo FX'!$B$1:$MY$1) -> 0.070972547 | Q9: =+Base!AA7 -> 45575 | R9: =+Base!AD7 -> 54523 | S9: =$T$3 -> 45392 | T9: =+NPV(V9,'Tabla desarrollo FX'!D8:MY8) -> 1723.2178 | U9: =+Base!AF7 -> 1719.0581 | V9: =+Base!Y7 -> 0.0057559073 | W9: =+Base!T7 -> 1664.23 | X9: =+Base!N7 -> 2700 | Y9: =+U9/X9 -> 0.63668818 | Z9: =+P9-Base!O7 -> -0.0043274531 | AA9: =+Base!U7 -> 12.508353 | AB9: =+Base!AL7*100 -> 16.448389 | AC9: =+Base!AM7*100 -> 37.966625 | AD9: =+Base!AG7 -> Los Libertadores 4733, Edificio F,departamento 106 | AE9: =+VLOOKUP(AF9,Comuna!A:B,2,0) -> 13101 | AF9: =+Base!AI7 -> Santiago
A10: =+Base!A8 -> 7 | B10: =+Base!B8 -> 202403260117A033 | C10: =+Base!F8 -> Lagos | D10: =+Base!G8 -> Muñoz | E10: =+Base!H8 -> Pablo Daniel | F10: =+Base!D8 -> 17747816 | G10: =+Base!E8 -> 4 | H10: =+Base!Z8 -> 45377 | I10: =+Base!T8 -> 1630.975 | J10: =+Base!M8 -> 550 | K10: =+L10-J10-I10 -> 69.025 | L10: =+Base!L8 -> 2250 | M10: 6 | N10: =+Base!Q8 -> 360 | O10: =+Base!R8+1 -> 6 | P10: =+XIRR('Tabla desarrollo FX'!B9:MY9,'Tabla desarrollo FX'!$B$1:$MY$1) -> 0.071001557 | Q10: =+Base!AA8 -> 45575 | R10: =+Base!AD8 -> 56349 | S10: =$T$3 -> 45392 | T10: =+NPV(V10,'Tabla desarrollo FX'!D9:MY9) -> 1695.5741 | U10: =+Base!AF8 -> 1691.4151 | V10: =+Base!Y8 -> 0.0057559073 | W10: =+Base!T8 -> 1630.975 | X10: =+Base!N8 -> 2460 | Y10: =+U10/X10 -> 0.68756711 | Z10: =+P10-Base!O8 -> -0.0042984435 | AA10: =+Base!U8 -> 11.548934 | AB10: =+Base!AL8*100 -> 33.391403 | AC10: =+Base!AM8*100 -> 49.056281 | AD10: =+Base!AG8 -> ADRIANA GARCIA IBAÑEZ 2030, Torre B,departamento 401 | AE10: =+VLOOKUP(AF10,Comuna!A:B,2,0) -> 7401 | AF10: =+Base!AI8 -> Linares
A11: =+Base!A9 -> 8 | B11: =+Base!B9 -> 202403220119A033 | C11: =+Base!F9 -> Jaña | D11: =+Base!G9 -> Avila | E11: =+Base!H9 -> Francisco Javier | F11: =+Base!D9 -> 17137105 | G11: =+Base!E9 -> 8 | H11: =+Base!Z9 -> 45373 | I11: =+Base!T9 -> 781.37 | J11: =+Base!M9 -> 400 | K11: =+L11-J11-I11 -> 218.63 | L11: =+Base!L9 -> 1400 | M11: 7 | N11: =+Base!Q9 -> 360 | O11: =+Base!R9+1 -> 6 | P11: =+XIRR('Tabla desarrollo FX'!B10:MY10,'Tabla desarrollo FX'!$B$1:$MY$1) -> 0.071001557 | Q11: =+Base!AA9 -> 45575 | R11: =+Base!AD9 -> 56349 | S11: =$T$3 -> 45392 | T11: =+NPV(V11,'Tabla desarrollo FX'!D10:MY10) -> 812.31826 | U11: =+Base!AF9 -> 809.82925 | V11: =+Base!Y9 -> 0.0057559073 | W11: =+Base!T9 -> 781.37 | X11: =+Base!N9 -> 1410 | Y11: =+U11/X11 -> 0.57434698 | Z11: =+P11-Base!O9 -> -0.0042984435 | AA11: =+Base!U9 -> 5.532881 | AB11: =+Base!AL9*100 -> 38.354014 | AC11: =+Base!AM9*100 -> 50.324471 | AD11: =+Base!AG9 -> Av. El Valle 199, Torre B,departamento 101 | AE11: =+VLOOKUP(AF11,Comuna!A:B,2,0) -> #N/A | AF11: =+Base!AI9 -> Cachapoal
A12: =+Base!A10 -> 9 | B12: =+Base!B10 -> 202403260120A033 | C12: =+Base!F10 -> Oñate | D12: =+Base!G10 -> Muñoz | E12: =+Base!H10 -> Pablo Enrique | F12: =+Base!D10 -> 16995140 | G12: =+Base!E10 -> 3 | H12: =+Base!Z10 -> 45377 | I12: =+Base!T10 -> 760 | J12: =+Base!M10 -> 600 | K12: =+L12-J12-I12 -> 40 | L12: =+Base!L10 -> 1400 | M12: 8 | N12: =+Base!Q10 -> 216 | O12: =+Base!R10+1 -> 6 | P12: =+XIRR('Tabla desarrollo FX'!B11:MY11,'Tabla desarrollo FX'!$B$1:$MY$1) -> 0.070901969 | Q12: =+Base!AA10 -> 45575 | R12: =+Base!AD10 -> 51966 | S12: =$T$3 -> 45392 | T12: =+NPV(V12,'Tabla desarrollo FX'!D11:MY11) -> 781.43864 | U12: =+Base!AF10 -> 779.0959 | V12: =+Base!Y10 -> 0.0057559073 | W12: =+Base!T10 -> 760 | X12: =+Base!N10 -> 1600 | Y12: =+U12/X12 -> 0.48693494 | Z12: =+P12-Base!O10 -> -0.0043980309 | AA12: =+Base!U10 -> 6.593 | AB12: =+Base!AL10*100 -> 15.83457 | AC12: =+Base!AM10*100 -> 40.708554 | AD12: =+Base!AG10 -> PROFESOR PASCUAL PEREIRA 1324,casa 1324 | AE12: =+VLOOKUP(AF12,Comuna!A:B,2,0) -> #N/A | AF12: =+Base!AI10 -> Biobío
A13: =+Base!A11 -> 10 | B13: =+Base!B11 -> 202403250121A033 | C13: =+Base!F11 -> Aranguiz | D13: =+Base!G11 -> Arevalo | E13: =+Base!H11 -> Macarena Andrea Del Carmen | F13: =+Base!D11 -> 18645373 | G13: =+Base!E11 -> 5 | H13: =+Base!Z11 -> 45376 | I13: =+Base!T11 -> 1672 | J13: =+Base!M11 -> 325 | K13: =+L13-J13-I13 -> 93 | L13: =+Base!L11 -> 2090 | M13: 9 | N13: =+Base!Q11 -> 360 | O13: =+Base!R11+1 -> 6 | P13: =+XIRR('Tabla desarrollo FX'!B12:MY12,'Tabla desarrollo FX'!$B$1:$MY$1) -> 0.071001557 | Q13: =+Base!AA11 -> 45575 | R13: =+Base!AD11 -> 56349 | S13: =$T$3 -> 45392 | T13: =+NPV(V13,'Tabla desarrollo FX'!D12:MY12) -> 1738.224 | U13: =+Base!AF11 -> 1733.8826 | V13: =+Base!Y11 -> 0.0057559073 | W13: =+Base!T11 -> 1672 | X13: =+Base!N11 -> 2200 | Y13: =+U13/X13 -> 0.78812843 | Z13: =+P13-Base!O11 -> -0.0042984435 | AA13: =+Base!U11 -> 11.839432 | AB13: =+Base!AL11*100 -> 24.855131 | AC13: =+Base!AM11*100 -> 39.683384 | AD13: =+Base!AG11 -> Av El Valle 199, Torre B,departamento 407 | AE13: =+VLOOKUP(AF13,Comuna!A:B,2,0) -> #N/A | AF13: =+Base!AI11 -> Cachapoal
A14: =+Base!A12 -> 11 | B14: =+Base!B12 -> 202403250123A033 | C14: =+Base!F12 -> Moraga | D14: =+Base!G12 -> Carrasco | E14: =+Base!H12 -> Jenny Alejandra | F14: =+Base!D12 -> 16681463 | G14: =+Base!E12 -> 4 | H14: =+Base!Z12 -> 45376 | I14: =+Base!T12 -> 877.78 | J14: =+Base!M12 -> 450 | K14: =+L14-J14-I14 -> 72.22 | L14: =+Base!L12 -> 1400 | M14: 10 | N14: =+Base!Q12 -> 240 | O14: =+Base!R12+1 -> 6 | P14: =+XIRR('Tabla desarrollo FX'!B13:MY13,'Tabla desarrollo FX'!$B$1:$MY$1) -> 0.070927659 | Q14: =+Base!AA12 -> 45575 | R14: =+Base!AD12 -> 52697 | S14: =$T$3 -> 45392 | T14: =+NPV(V14,'Tabla desarrollo FX'!D13:MY13) -> 904.51418 | U14: =+Base!AF12 -> 902.65751 | V14: =+Base!Y12 -> 0.0057559073 | W14: =+Base!T12 -> 877.78 | X14: =+Base!N12 -> 1400 | Y14: =+U14/X14 -> 0.64475536 | Z14: =+P14-Base!O12 -> -0.0043723413 | AA14: =+Base!U12 -> 7.236418 | AB14: =+Base!AL12*100 -> 27.580802 | AC14: =+Base!AM12*100 -> 28.908034 | AD14: =+Base!AG12 -> PASAJE DEMOFILA TORREALBA (PROFESORA) 1744,casa 1744 | AE14: =+VLOOKUP(AF14,Comuna!A:B,2,0) -> #N/A | AF14: =+Base!AI12 -> Cachapoal
A15: =+Base!A13 -> 12 | B15: =+Base!B13 -> 202403250125A033 | C15: =+Base!F13 -> Pozo | D15: =+Base!G13 -> Salvatierra | E15: =+Base!H13 -> Eufronia | F15: =+Base!D13 -> 24243822 | G15: =+Base!E13 -> 1 | H15: =+Base!Z13 -> 45376 | I15: =+Base!T13 -> 766.75 | J15: =+Base!M13 -> 737.5 | K15: =+L15-J15-I15 -> 195.75 | L15: =+Base!L13 -> 1700 | M15: 11 | N15: =+Base!Q13 -> 204 | O15: =+Base!R13+1 -> 6 | P15: =+XIRR('Tabla desarrollo FX'!B14:MY14,'Tabla desarrollo FX'!$B$1:$MY$1) -> 0.070887038 | Q15: =+Base!AA13 -> 45575 | R15: =+Base!AD13 -> 51601 | S15: =$T$3 -> 45392 | T15: =+NPV(V15,'Tabla desarrollo FX'!D14:MY14) -> 787.48094 | U15: =+Base!AF13 -> 785.37074 | V15: =+Base!Y13 -> 0.0057559073 | W15: =+Base!T13 -> 766.75 | X15: =+Base!N13 -> 1700 | Y15: =+U15/X15 -> 0.46198279 | Z15: =+P15-Base!O13 -> -0.0044129619 | AA15: =+Base!U13 -> 6.850911 | AB15: =+Base!AL13*100 -> 41.766992 | AC15: =+Base!AM13*100 -> 44.378192 | AD15: =+Base!AG13 -> Los Libertadores 4733, Edificio F,departamento 808 | AE15: =+VLOOKUP(AF15,Comuna!A:B,2,0) -> 13101 | AF15: =+Base!AI13 -> Santiago
... A23: =+Base!A21 -> 20 | B23: =+Base!B21 -> 202403250138A033 | C23: =+Base!F21 -> Rivera | D23: =+Base!G21 -> De Carreño | E23: =+Base!H21 -> Rosmery Josefina | F23: =+Base!D21 -> 27097423 | G23: =+Base!E21 -> 6 | H23: =+Base!Z21 -> 45376 | I23: =+Base!T21 -> 1860 | J23: =+Base!M21 -> 700 | K23: =+L23-J23-I23 -> 240 | L23: =+Base!L21 -> 2800 | M23: 19 | N23: =+Base!Q21 -> 360 | O23: =+Base!R21+1 -> 6 | P23: =+XIRR('Tabla desarrollo FX'!B22:MY22,'Tabla desarrollo FX'!$B$1:$MY$1) -> 0.071001557 | Q23: =+Base!AA21 -> 45575 | R23: =+Base!AD21 -> 56349 | S23: =$T$3 -> 45392 | T23: =+NPV(V23,'Tabla desarrollo FX'!D22:MY22) -> 1933.5734 | U23: =+Base!AF21 -> 1928.6521 | V23: =+Base!Y21 -> 0.0057559073 | W23: =+Base!T21 -> 1860 | X23: =+Base!N21 -> 2800 | Y23: =+U23/X23 -> 0.68880432 | Z23: =+P23-Base!O21 -> -0.0042984435 | AA23: =+Base!U21 -> 13.17 | AB23: =+Base!AL21*100 -> 17.73358 | AC23: =+Base!AM21*100 -> 21.092959 | AD23: =+Base!AG21 -> Los Libertadores 4733, Edificio H | AE23: =+VLOOKUP(AF23,Comuna!A:B,2,0) -> 13101 | AF23: =+Base!AI21 -> Santiago

Sheet Valo
U1: =+SUM(U4:U23) -> 28137.957 | V1: 1 | X1: 1
I2: Monto Crédito + Cap (UF) | P2: Tasa endoso | Q2: Fecha 1er Aporte a endosar | R2: Fecha Last Aporte | S2: Fecha Corte | U2: VPN | V2: Tasa mensual de endoso | X2: Tasacion | Y2: Precio Venta/Tasación | Z2: Tasa Endoso | AA2: Monto Dividendo | AB2: Dividendo/ Renta | AC2: Carga Financiera/ Renta
A3: Nº | B3: N° Operación | C3: Apellido paterno | D3: Apellido materno | E3: Nombres | F3: Rut | G3: DV | H3: Leasing o Mutuo | J3: Subsidio | K3: Pie | L3: Valor Vivienda | M3: Morosidad | N3: Nº Cuotas | O3: Primera cuota a endosar | T3: 45392 | U3: 45379 | W3: Saldo insoluto Teórico | AD3: Dirección de la Propiedad | AE3: Codigo Comuna | AF3: Comuna
A4: 1 | B4: 202403250103A033 | C4: Diaz | D4: Zuñiga | E4: Joel Alejandro | F4: 18803188 | G4: 9 | H4: 45376 | I4: 1595 | J4: 525 | K4: 80 | L4: 2200 | M4: 0 | N4: 300 | O4: 6 | P4: 0.070972547 | Q4: 45575 | R4: 54523 | S4: 45392 | T4: 1651.534 | U4: 1647.6019 | V4: 0.0057559073 | W4: 1595 | X4: 2325 | Y4: 0.70864598 | Z4: -0.0043274531 | AA4: 11.98802 | AB4: 25.914525 | AC4: 32.831376 | AD4: Calle 8 Sur Poniente 351,casa 351 | AE4: 7401 | AF4: Biobío
A5: 2 | B5: 202403260104A033 | C5: Hultazo | D5: Novoa | E5: Daniela Del Carmen | F5: 16265854 | G5: 9 | H5: 45377 | I5: 1480.48 | J5: 550 | K5: 169.52 | L5: 2200 | M5: 1 | N5: 360 | O5: 6 | P5: 0.071001557 | Q5: 45575 | R5: 56349 | S5: 45392 | T5: 1539.1184 | U5: 1534.7211 | V5: 0.0057559073 | W5: 1480.48 | X5: 2560 | Y5: 0.59950042 | Z5: -0.0042984435 | AA5: 10.483279 | AB5: 17.374483 | AC5: 46.168658 | AD5: ADRIANA GARCIA IBAÑEZ 2030, Edificio G,departamento 303 | AE5: 7401 | AF5: Linares
A6: 3 | B6: 202403250105A033 | C6: Salazar | D6: Carvajal | E6: Nedier Graciela | F6: 24585394 | G6: 7 | H6: 45376 | I6: 863.96 | J6: 450 | K6: 86.04 | L6: 1400 | M6: 2 | N6: 312 | O6: 6 | P6: 0.070979336 | Q6: 45575 | R6: 54888 | S6: 45392 | T6: 895.357 | U6: 892.6874 | V6: 0.0057559073 | W6: 863.96 | X6: 1400 | Y6: 0.63763386 | Z6: -0.0043206641 | AA6: 6.402808 | AB6: 34.565539 | AC6: 54.730716 | AD6: Camino La Vara 02600, Torre 1,departamento 406 | AE6: 7401 | AF6: Maipo
A7: 4 | B7: 202403260108A033 | C7: Vasquez | D7: Sanchez | E7: Bertha Ramona | F7: 26537872 | G7: 2 | H7: 45377 | I7: 1717 | J7: 475 | K7: 108 | L7: 2300 | M7: 3 | N7: 264 | O7: 6 | P7: 0.070948073 | Q7: 45575 | R7: 53427 | S7: 45392 | T7: 1772.9012 | U7: 1768.2353 | V7: 0.0057559073 | W7: 1717 | X7: 2300 | Y7: 0.76879796 | Z7: -0.0043519267 | AA7: 13.571168 | AB7: 36.411949 | AC7: 41.283351 | AD7: Calle 38 Oriente 350, Torre 8,departamento 2804 | AE7: 7401 | AF7: Talca
A8: 5 | B8: 202403250112A033 | C8: Huenchul | D8: Colihuinca | E8: César Antonio | F8: 18188333 | G8: 2 | H8: 45376 | I8: 1551.6 | J8: 375 | K8: 143.4 | L8: 2070 | M8: 4 | N8: 360 | O8: 6 | P8: 0.071001557 | Q8: 45575 | R8: 56349 | S8: 45392 | T8: 1613.0553 | U8: 1609.4065 | V8: 0.0057559073 | W8: 1551.6 | X8: 2400 | Y8: 0.67058603 | Z8: -0.0042984435 | AA8: 10.98688 | AB8: 40.025143 | AC8: 42.269568 | AD8: Camino La Vara 02600, TORRE 2,departamento 412 | AE8: 7401 | AF8: Maipo
A9: 6 | B9: 202403260115A033 | C9: Rojas | D9: Diaz | E9: Claudio Sebastian | F9: 18250306 | G9: 1 | H9: 45377 | I9: 1664.23 | J9: 700 | K9: 335.77 | L9: 2700 | M9: 5 | N9: 300 | O9: 6 | P9: 0.070972547 | Q9: 45575 | R9: 54523 | S9: 45392 | T9: 1723.2178 | U9: 1719.0581 | V9: 0.0057559073 | W9: 1664.23 | X9: 2700 | Y9: 0.63668818 | Z9: -0.0043274531 | AA9: 12.508353 | AB9: 16.448389 | AC9: 37.966625 | AD9: Los Libertadores 4733, Edificio F,departamento 106 | AE9: 13101 | AF9: Santiago
A10: 7 | B10: 202403260117A033 | C10: Lagos | D10: Muñoz | E10: Pablo Daniel | F10: 17747816 | G10: 4 | H10: 45377 | I10: 1630.975 | J10: 550 | K10: 69.025 | L10: 2250 | M10: 6 | N10: 360 | O10: 6 | P10: 0.071001557 | Q10: 45575 | R10: 56349 | S10: 45392 | T10: 1695.5741 | U10: 1691.4151 | V10: 0.0057559073 | W10: 1630.975 | X10: 2460 | Y10: 0.68756711 | Z10: -0.0042984435 | AA10: 11.548934 | AB10: 33.391403 | AC10: 49.056281 | AD10: ADRIANA GARCIA IBAÑEZ 2030, Torre B,departamento 401 | AE10: 7401 | AF10: Linares
A11: 8 | B11: 202403220119A033 | C11: Jaña | D11: Avila | E11: Francisco Javier | F11: 17137105 | G11: 8 | H11: 45373 | I11: 781.37 | J11: 400 | K11: 218.63 | L11: 1400 | M11: 7 | N11: 360 | O11: 6 | P11: 0.071001557 | Q11: 45575 | R11: 56349 | S11: 45392 | T11: 812.31826 | U11: 809.82925 | V11: 0.0057559073 | W11: 781.37 | X11: 1410 | Y11: 0.57434698 | Z11: -0.0042984435 | AA11: 5.532881 | AB11: 38.354014 | AC11: 50.324471 | AD11: Av. El Valle 199, Torre B,departamento 101 | AE11: 7401 | AF11: Cachapoal
A12: 9 | B12: 202403260120A033 | C12: Oñate | D12: Muñoz | E12: Pablo Enrique | F12: 16995140 | G12: 3 | H12: 45377 | I12: 760 | J12: 600 | K12: 40 | L12: 1400 | M12: 8 | N12: 216 | O12: 6 | P12: 0.070901969 | Q12: 45575 | R12: 51966 | S12: 45392 | T12: 781.43864 | U12: 779.0959 | V12: 0.0057559073 | W12: 760 | X12: 1600 | Y12: 0.48693494 | Z12: -0.0043980309 | AA12: 6.593 | AB12: 15.83457 | AC12: 40.708554 | AD12: PROFESOR PASCUAL PEREIRA 1324,casa 1324 | AE12: 7401 | AF12: Biobío
A13: 10 | B13: 202403250121A033 | C13: Aranguiz | D13: Arevalo | E13: Macarena Andrea Del Carmen | F13: 18645373 | G13: 5 | H13: 45376 | I13: 1672 | J13: 325 | K13: 93 | L13: 2090 | M13: 9 | N13: 360 | O13: 6 | P13: 0.071001557 | Q13: 45575 | R13: 56349 | S13: 45392 | T13: 1738.224 | U13: 1733.8826 | V13: 0.0057559073 | W13: 1672 | X13: 2200 | Y13: 0.78812843 | Z13: -0.0042984435 | AA13: 11.839432 | AB13: 24.855131 | AC13: 39.683384 | AD13: Av El Valle 199, Torre B,departamento 407 | AE13: 7401 | AF13: Cachapoal
A14: 11 | B14: 202403250123A033 | C14: Moraga | D14: Carrasco | E14: Jenny Alejandra | F14: 16681463 | G14: 4 | H14: 45376 | I14: 877.78 | J14: 450 | K14: 72.22 | L14: 1400 | M14: 10 | N14: 240 | O14: 6 | P14: 0.070927659 | Q14: 45575 | R14: 52697 | S14: 45392 | T14: 904.51418 | U14: 902.65751 | V14: 0.0057559073 | W14: 877.78 | X14: 1400 | Y14: 0.64475536 | Z14: -0.0043723413 | AA14: 7.236418 | AB14: 27.580802 | AC14: 28.908034 | AD14: PASAJE DEMOFILA TORREALBA (PROFESORA) 1744,casa 1744 | AE14: 7401 | AF14: Cachapoal
A15: 12 | B15: 202403250125A033 | C15: Pozo | D15: Salvatierra | E15: Eufronia | F15: 24243822 | G15: 1 | H15: 45376 | I15: 766.75 | J15: 737.5 | K15: 195.75 | L15: 1700 | M15: 11 | N15: 204 | O15: 6 | P15: 0.070887038 | Q15: 45575 | R15: 51601 | S15: 45392 | T15: 787.48094 | U15: 785.37074 | V15: 0.0057559073 | W15: 766.75 | X15: 1700 | Y15: 0.46198279 | Z15: -0.0044129619 | AA15: 6.850911 | AB15: 41.766992 | AC15: 44.378192 | AD15: Los Libertadores 4733, Edificio F,departamento 808 | AE15: 13101 | AF15: Santiago
... A23: 20 | B23: 202403250138A033 | C23: Rivera | D23: De Carreño | E23: Rosmery Josefina | F23: 27097423 | G23: 6 | H23: 45376 | I23: 1860 | J23: 700 | K23: 240 | L23: 2800 | M23: 19 | N23: 360 | O23: 6 | P23: 0.071001557 | Q23: 45575 | R23: 56349 | S23: 45392 | T23: 1933.5734 | U23: 1928.6521 | V23: 0.0057559073 | W23: 1860 | X23: 2800 | Y23: 0.68880432 | Z23: -0.0042984435 | AA23: 13.17 | AB23: 17.73358 | AC23: 21.092959 | AD23: Los Libertadores 4733, Edificio H | AE23: 13101 | AF23: Santiago

Sheet Tabla desarrollo FX
B1: =+'Valo FX'!U3 -> 45379 | C1: ='Valo FX'!T3 -> 45392 | D1: =EDATE(C1,1) -> 45422 | E1: =EDATE(D1,1) -> 45453 | F1: =EDATE(E1,1) -> 45483 | G1: =EDATE(F1,1) -> 45514 | H1: =EDATE(G1,1) -> 45545 | I1: =EDATE(H1,1) -> 45575 | J1: =EDATE(I1,1) -> 45606 | K1: =EDATE(J1,1) -> 45636 | ... MY1: =EDATE(MX1,1) -> 56349
A2: Nº | B2: Primera cuota a endosar | C2: 1 | D2: =C2+1 -> 2 | E2: =D2+1 -> 3 | F2: =E2+1 -> 4 | G2: =F2+1 -> 5 | H2: =G2+1 -> 6 | I2: =H2+1 -> 7 | J2: =I2+1 -> 8 | K2: =J2+1 -> 9 | ... MY2: =MX2+1 -> 361
A3: =+'Valo FX'!A4 -> 1 | B3: =-'Valo FX'!T4 -> -1651.534 | C3: =IF(C$1<INDEX('Valo FX'!$Q:$Q,MATCH($A3,'Valo FX'!$A:$A,0)),0,IF(C$1<INDEX('Valo FX'!$R:$R,MATCH($A3,'Valo FX'!$A:$A,0)),INDEX(Base!$U:$U,MATCH($A3,Base!$A:$A,0)),IF(C$1=INDEX('Valo FX'!$R:$R,MATCH($A3,'Valo FX'!$A:$A,0)),INDEX(Base!$V:$V,MATCH($A3,Base!$A:$A,0)),0))) -> 0 | D3: =IF(D$1<INDEX('Valo FX'!$Q:$Q,MATCH($A3,'Valo FX'!$A:$A,0)),0,IF(D$1<INDEX('Valo FX'!$R:$R,MATCH($A3,'Valo FX'!$A:$A,0)),INDEX(Base!$U:$U,MATCH($A3,Base!$A:$A,0)),IF(D$1=INDEX('Valo FX'!$R:$R,MATCH($A3,'Valo FX'!$A:$A,0)),INDEX(Base!$V:$V,MATCH($A3,Base!$A:$A,0)),0))) -> 0 | E3: =IF(E$1<INDEX('Valo FX'!$Q:$Q,MATCH($A3,'Valo FX'!$A:$A,0)),0,IF(E$1<INDEX('Valo FX'!$R:$R,MATCH($A3,'Valo FX'!$A:$A,0)),INDEX(Base!$U:$U,MATCH($A3,Base!$A:$A,0)),IF(E$1=INDEX('Valo FX'!$R:$R,MATCH($A3,'Valo FX'!$A:$A,0)),INDEX(Base!$V:$V,MATCH($A3,Base!$A:$A,0)),0))) -> 0 | F3: =IF(F$1<INDEX('Valo FX'!$Q:$Q,MATCH($A3,'Valo FX'!$A:$A,0)),0,IF(F$1<INDEX('Valo FX'!$R:$R,MATCH($A3,'Valo FX'!$A:$A,0)),INDEX(Base!$U:$U,MATCH($A3,Base!$A:$A,0)),IF(F$1=INDEX('Valo FX'!$R:$R,MATCH($A3,'Valo FX'!$A:$A,0)),INDEX(Base!$V:$V,MATCH($A3,Base!$A:$A,0)),0))) -> 0 | G3: =IF(G$1<INDEX('Valo FX'!$Q:$Q,MATCH($A3,'Valo FX'!$A:$A,0)),0,IF(G$1<INDEX('Valo FX'!$R:$R,MATCH($A3,'Valo FX'!$A:$A,0)),INDEX(Base!$U:$U,MATCH($A3,Base!$A:$A,0)),IF(G$1=INDEX('Valo FX'!$R:$R,MATCH($A3,'Valo FX'!$A:$A,0)),INDEX(Base!$V:$V,MATCH($A3,Base!$A:$A,0)),0))) -> 0 | H3: =IF(H$1<INDEX('Valo FX'!$Q:$Q,MATCH($A3,'Valo FX'!$A:$A,0)),0,IF(H$1<INDEX('Valo FX'!$R:$R,MATCH($A3,'Valo FX'!$A:$A,0)),INDEX(Base!$U:$U,MATCH($A3,Base!$A:$A,0)),IF(H$1=INDEX('Valo FX'!$R:$R,MATCH($A3,'Valo FX'!$A:$A,0)),INDEX(Base!$V:$V,MATCH($A3,Base!$A:$A,0)),0))) -> 0 | I3: =IF(I$1<INDEX('Valo FX'!$Q:$Q,MATCH($A3,'Valo FX'!$A:$A,0)),0,IF(I$1<INDEX('Valo FX'!$R:$R,MATCH($A3,'Valo FX'!$A:$A,0)),INDEX(Base!$U:$U,MATCH($A3,Base!$A:$A,0)),IF(I$1=INDEX('Valo FX'!$R:$R,MATCH($A3,'Valo FX'!$A:$A,0)),INDEX(Base!$V:$V,MATCH($A3,Base!$A:$A,0)),0))) -> 11.98802 | J3: =IF(J$1<INDEX('Valo FX'!$Q:$Q,MATCH($A3,'Valo FX'!$A:$A,0)),0,IF(J$1<INDEX('Valo FX'!$R:$R,MATCH($A3,'Valo FX'!$A:$A,0)),INDEX(Base!$U:$U,MATCH($A3,Base!$A:$A,0)),IF(J$1=INDEX('Valo FX'!$R:$R,MATCH($A3,'Valo FX'!$A:$A,0)),INDEX(Base!$V:$V,MATCH($A3,Base!$A:$A,0)),0))) -> 11.98802 | ... MY3: =IF(MY$1<INDEX('Valo FX'!$Q:$Q,MATCH($A3,'Valo FX'!$A:$A,0)),0,IF(MY$1<INDEX('Valo FX'!$R:$R,MATCH($A3,'Valo FX'!$A:$A,0)),INDEX(Base!$U:$U,MATCH($A3,Base!$A:$A,0)),IF(MY$1=INDEX('Valo FX'!$R:$R,MATCH($A3,'Valo FX'!$A:$A,0)),INDEX(Base!$V:$V,MATCH($A3,Base!$A:$A,0)),0))) -> 0
A4: =+'Valo FX'!A5 -> 2 | B4: =-'Valo FX'!T5 -> -1539.1184 | C4: =IF(C$1<INDEX('Valo FX'!$Q:$Q,MATCH($A4,'Valo FX'!$A:$A,0)),0,IF(C$1<INDEX('Valo FX'!$R:$R,MATCH($A4,'Valo FX'!$A:$A,0)),INDEX(Base!$U:$U,MATCH($A4,Base!$A:$A,0)),IF(C$1=INDEX('Valo FX'!$R:$R,MATCH($A4,'Valo FX'!$A:$A,0)),INDEX(Base!$V:$V,MATCH($A4,Base!$A:$A,0)),0))) -> 0 | D4: =IF(D$1<INDEX('Valo FX'!$Q:$Q,MATCH($A4,'Valo FX'!$A:$A,0)),0,IF(D$1<INDEX('Valo FX'!$R:$R,MATCH($A4,'Valo FX'!$A:$A,0)),INDEX(Base!$U:$U,MATCH($A4,Base!$A:$A,0)),IF(D$1=INDEX('Valo FX'!$R:$R,MATCH($A4,'Valo FX'!$A:$A,0)),INDEX(Base!$V:$V,MATCH($A4,Base!$A:$A,0)),0))) -> 0 | E4: =IF(E$1<INDEX('Valo FX'!$Q:$Q,MATCH($A4,'Valo FX'!$A:$A,0)),0,IF(E$1<INDEX('Valo FX'!$R:$R,MATCH($A4,'Valo FX'!$A:$A,0)),INDEX(Base!$U:$U,MATCH($A4,Base!$A:$A,0)),IF(E$1=INDEX('Valo FX'!$R:$R,MATCH($A4,'Valo FX'!$A:$A,0)),INDEX(Base!$V:$V,MATCH($A4,Base!$A:$A,0)),0))) -> 0 | F4: =IF(F$1<INDEX('Valo FX'!$Q:$Q,MATCH($A4,'Valo FX'!$A:$A,0)),0,IF(F$1<INDEX('Valo FX'!$R:$R,MATCH($A4,'Valo FX'!$A:$A,0)),INDEX(Base!$U:$U,MATCH($A4,Base!$A:$A,0)),IF(F$1=INDEX('Valo FX'!$R:$R,MATCH($A4,'Valo FX'!$A:$A,0)),INDEX(Base!$V:$V,MATCH($A4,Base!$A:$A,0)),0))) -> 0 | G4: =IF(G$1<INDEX('Valo FX'!$Q:$Q,MATCH($A4,'Valo FX'!$A:$A,0)),0,IF(G$1<INDEX('Valo FX'!$R:$R,MATCH($A4,'Valo FX'!$A:$A,0)),INDEX(Base!$U:$U,MATCH($A4,Base!$A:$A,0)),IF(G$1=INDEX('Valo FX'!$R:$R,MATCH($A4,'Valo FX'!$A:$A,0)),INDEX(Base!$V:$V,MATCH($A4,Base!$A:$A,0)),0))) -> 0 | H4: =IF(H$1<INDEX('Valo FX'!$Q:$Q,MATCH($A4,'Valo FX'!$A:$A,0)),0,IF(H$1<INDEX('Valo FX'!$R:$R,MATCH($A4,'Valo FX'!$A:$A,0)),INDEX(Base!$U:$U,MATCH($A4,Base!$A:$A,0)),IF(H$1=INDEX('Valo FX'!$R:$R,MATCH($A4,'Valo FX'!$A:$A,0)),INDEX(Base!$V:$V,MATCH($A4,Base!$A:$A,0)),0))) -> 0 | I4: =IF(I$1<INDEX('Valo FX'!$Q:$Q,MATCH($A4,'Valo FX'!$A:$A,0)),0,IF(I$1<INDEX('Valo FX'!$R:$R,MATCH($A4,'Valo FX'!$A:$A,0)),INDEX(Base!$U:$U,MATCH($A4,Base!$A:$A,0)),IF(I$1=INDEX('Valo FX'!$R:$R,MATCH($A4,'Valo FX'!$A:$A,0)),INDEX(Base!$V:$V,MATCH($A4,Base!$A:$A,0)),0))) -> 10.483279 | J4: =IF(J$1<INDEX('Valo FX'!$Q:$Q,MATCH($A4,'Valo FX'!$A:$A,0)),0,IF(J$1<INDEX('Valo FX'!$R:$R,MATCH($A4,'Valo FX'!$A:$A,0)),INDEX(Base!$U:$U,MATCH($A4,Base!$A:$A,0)),IF(J$1=INDEX('Valo FX'!$R:$R,MATCH($A4,'Valo FX'!$A:$A,0)),INDEX(Base!$V:$V,MATCH($A4,Base!$A:$A,0)),0))) -> 10.483279 | ... MY4: =IF(MY$1<INDEX('Valo FX'!$Q:$Q,MATCH($A4,'Valo FX'!$A:$A,0)),0,IF(MY$1<INDEX('Valo FX'!$R:$R,MATCH($A4,'Valo FX'!$A:$A,0)),INDEX(Base!$U:$U,MATCH($A4,Base!$A:$A,0)),IF(MY$1=INDEX('Valo FX'!$R:$R,MATCH($A4,'Valo FX'!$A:$A,0)),INDEX(Base!$V:$V,MATCH($A4,Base!$A:$A,0)),0))) -> 10.761609
A5: =+'Valo FX'!A6 -> 3 | B5: =-'Valo FX'!T6 -> -895.357 | C5: =IF(C$1<INDEX('Valo FX'!$Q:$Q,MATCH($A5,'Valo FX'!$A:$A,0)),0,IF(C$1<INDEX('Valo FX'!$R:$R,MATCH($A5,'Valo FX'!$A:$A,0)),INDEX(Base!$U:$U,MATCH($A5,Base!$A:$A,0)),IF(C$1=INDEX('Valo FX'!$R:$R,MATCH($A5,'Valo FX'!$A:$A,0)),INDEX(Base!$V:$V,MATCH($A5,Base!$A:$A,0)),0))) -> 0 | D5: =IF(D$1<INDEX('Valo FX'!$Q:$Q,MATCH($A5,'Valo FX'!$A:$A,0)),0,IF(D$1<INDEX('Valo FX'!$R:$R,MATCH($A5,'Valo FX'!$A:$A,0)),INDEX(Base!$U:$U,MATCH($A5,Base!$A:$A,0)),IF(D$1=INDEX('Valo FX'!$R:$R,MATCH($A5,'Valo FX'!$A:$A,0)),INDEX(Base!$V:$V,MATCH($A5,Base!$A:$A,0)),0))) -> 0 | E5: =IF(E$1<INDEX('Valo FX'!$Q:$Q,MATCH($A5,'Valo FX'!$A:$A,0)),0,IF(E$1<INDEX('Valo FX'!$R:$R,MATCH($A5,'Valo FX'!$A:$A,0)),INDEX(Base!$U:$U,MATCH($A5,Base!$A:$A,0)),IF(E$1=INDEX('Valo FX'!$R:$R,MATCH($A5,'Valo FX'!$A:$A,0)),INDEX(Base!$V:$V,MATCH($A5,Base!$A:$A,0)),0))) -> 0 | F5: =IF(F$1<INDEX('Valo FX'!$Q:$Q,MATCH($A5,'Valo FX'!$A:$A,0)),0,IF(F$1<INDEX('Valo FX'!$R:$R,MATCH($A5,'Valo FX'!$A:$A,0)),INDEX(Base!$U:$U,MATCH($A5,Base!$A:$A,0)),IF(F$1=INDEX('Valo FX'!$R:$R,MATCH($A5,'Valo FX'!$A:$A,0)),INDEX(Base!$V:$V,MATCH($A5,Base!$A:$A,0)),0))) -> 0 | G5: =IF(G$1<INDEX('Valo FX'!$Q:$Q,MATCH($A5,'Valo FX'!$A:$A,0)),0,IF(G$1<INDEX('Valo FX'!$R:$R,MATCH($A5,'Valo FX'!$A:$A,0)),INDEX(Base!$U:$U,MATCH($A5,Base!$A:$A,0)),IF(G$1=INDEX('Valo FX'!$R:$R,MATCH($A5,'Valo FX'!$A:$A,0)),INDEX(Base!$V:$V,MATCH($A5,Base!$A:$A,0)),0))) -> 0 | H5: =IF(H$1<INDEX('Valo FX'!$Q:$Q,MATCH($A5,'Valo FX'!$A:$A,0)),0,IF(H$1<INDEX('Valo FX'!$R:$R,MATCH($A5,'Valo FX'!$A:$A,0)),INDEX(Base!$U:$U,MATCH($A5,Base!$A:$A,0)),IF(H$1=INDEX('Valo FX'!$R:$R,MATCH($A5,'Valo FX'!$A:$A,0)),INDEX(Base!$V:$V,MATCH($A5,Base!$A:$A,0)),0))) -> 0 | I5: =IF(I$1<INDEX('Valo FX'!$Q:$Q,MATCH($A5,'Valo FX'!$A:$A,0)),0,IF(I$1<INDEX('Valo FX'!$R:$R,MATCH($A5,'Valo FX'!$A:$A,0)),INDEX(Base!$U:$U,MATCH($A5,Base!$A:$A,0)),IF(I$1=INDEX('Valo FX'!$R:$R,MATCH($A5,'Valo FX'!$A:$A,0)),INDEX(Base!$V:$V,MATCH($A5,Base!$A:$A,0)),0))) -> 6.402808 | J5: =IF(J$1<INDEX('Valo FX'!$Q:$Q,MATCH($A5,'Valo FX'!$A:$A,0)),0,IF(J$1<INDEX('Valo FX'!$R:$R,MATCH($A5,'Valo FX'!$A:$A,0)),INDEX(Base!$U:$U,MATCH($A5,Base!$A:$A,0)),IF(J$1=INDEX('Valo FX'!$R:$R,MATCH($A5,'Valo FX'!$A:$A,0)),INDEX(Base!$V:$V,MATCH($A5,Base!$A:$A,0)),0))) -> 6.402808 | ... MY5: =IF(MY$1<INDEX('Valo FX'!$Q:$Q,MATCH($A5,'Valo FX'!$A:$A,0)),0,IF(MY$1<INDEX('Valo FX'!$R:$R,MATCH($A5,'Valo FX'!$A:$A,0)),INDEX(Base!$U:$U,MATCH($A5,Base!$A:$A,0)),IF(MY$1=INDEX('Valo FX'!$R:$R,MATCH($A5,'Valo FX'!$A:$A,0)),INDEX(Base!$V:$V,MATCH($A5,Base!$A:$A,0)),0))) -> 0
A6: =+'Valo FX'!A7 -> 4 | B6: =-'Valo FX'!T7 -> -1772.9012 | C6: =IF(C$1<INDEX('Valo FX'!$Q:$Q,MATCH($A6,'Valo FX'!$A:$A,0)),0,IF(C$1<INDEX('Valo FX'!$R:$R,MATCH($A6,'Valo FX'!$A:$A,0)),INDEX(Base!$U:$U,MATCH($A6,Base!$A:$A,0)),IF(C$1=INDEX('Valo FX'!$R:$R,MATCH($A6,'Valo FX'!$A:$A,0)),INDEX(Base!$V:$V,MATCH($A6,Base!$A:$A,0)),0))) -> 0 | D6: =IF(D$1<INDEX('Valo FX'!$Q:$Q,MATCH($A6,'Valo FX'!$A:$A,0)),0,IF(D$1<INDEX('Valo FX'!$R:$R,MATCH($A6,'Valo FX'!$A:$A,0)),INDEX(Base!$U:$U,MATCH($A6,Base!$A:$A,0)),IF(D$1=INDEX('Valo FX'!$R:$R,MATCH($A6,'Valo FX'!$A:$A,0)),INDEX(Base!$V:$V,MATCH($A6,Base!$A:$A,0)),0))) -> 0 | E6: =IF(E$1<INDEX('Valo FX'!$Q:$Q,MATCH($A6,'Valo FX'!$A:$A,0)),0,IF(E$1<INDEX('Valo FX'!$R:$R,MATCH($A6,'Valo FX'!$A:$A,0)),INDEX(Base!$U:$U,MATCH($A6,Base!$A:$A,0)),IF(E$1=INDEX('Valo FX'!$R:$R,MATCH($A6,'Valo FX'!$A:$A,0)),INDEX(Base!$V:$V,MATCH($A6,Base!$A:$A,0)),0))) -> 0 | F6: =IF(F$1<INDEX('Valo FX'!$Q:$Q,MATCH($A6,'Valo FX'!$A:$A,0)),0,IF(F$1<INDEX('Valo FX'!$R:$R,MATCH($A6,'Valo FX'!$A:$A,0)),INDEX(Base!$U:$U,MATCH($A6,Base!$A:$A,0)),IF(F$1=INDEX('Valo FX'!$R:$R,MATCH($A6,'Valo FX'!$A:$A,0)),INDEX(Base!$V:$V,MATCH($A6,Base!$A:$A,0)),0))) -> 0 | G6: =IF(G$1<INDEX('Valo FX'!$Q:$Q,MATCH($A6,'Valo FX'!$A:$A,0)),0,IF(G$1<INDEX('Valo FX'!$R:$R,MATCH($A6,'Valo FX'!$A:$A,0)),INDEX(Base!$U:$U,MATCH($A6,Base!$A:$A,0)),IF(G$1=INDEX('Valo FX'!$R:$R,MATCH($A6,'Valo FX'!$A:$A,0)),INDEX(Base!$V:$V,MATCH($A6,Base!$A:$A,0)),0))) -> 0 | H6: =IF(H$1<INDEX('Valo FX'!$Q:$Q,MATCH($A6,'Valo FX'!$A:$A,0)),0,IF(H$1<INDEX('Valo FX'!$R:$R,MATCH($A6,'Valo FX'!$A:$A,0)),INDEX(Base!$U:$U,MATCH($A6,Base!$A:$A,0)),IF(H$1=INDEX('Valo FX'!$R:$R,MATCH($A6,'Valo FX'!$A:$A,0)),INDEX(Base!$V:$V,MATCH($A6,Base!$A:$A,0)),0))) -> 0 | I6: =IF(I$1<INDEX('Valo FX'!$Q:$Q,MATCH($A6,'Valo FX'!$A:$A,0)),0,IF(I$1<INDEX('Valo FX'!$R:$R,MATCH($A6,'Valo FX'!$A:$A,0)),INDEX(Base!$U:$U,MATCH($A6,Base!$A:$A,0)),IF(I$1=INDEX('Valo FX'!$R:$R,MATCH($A6,'Valo FX'!$A:$A,0)),INDEX(Base!$V:$V,MATCH($A6,Base!$A:$A,0)),0))) -> 13.571168 | J6: =IF(J$1<INDEX('Valo FX'!$Q:$Q,MATCH($A6,'Valo FX'!$A:$A,0)),0,IF(J$1<INDEX('Valo FX'!$R:$R,MATCH($A6,'Valo FX'!$A:$A,0)),INDEX(Base!$U:$U,MATCH($A6,Base!$A:$A,0)),IF(J$1=INDEX('Valo FX'!$R:$R,MATCH($A6,'Valo FX'!$A:$A,0)),INDEX(Base!$V:$V,MATCH($A6,Base!$A:$A,0)),0))) -> 13.571168 | ... MY6: =IF(MY$1<INDEX('Valo FX'!$Q:$Q,MATCH($A6,'Valo FX'!$A:$A,0)),0,IF(MY$1<INDEX('Valo FX'!$R:$R,MATCH($A6,'Valo FX'!$A:$A,0)),INDEX(Base!$U:$U,MATCH($A6,Base!$A:$A,0)),IF(MY$1=INDEX('Valo FX'!$R:$R,MATCH($A6,'Valo FX'!$A:$A,0)),INDEX(Base!$V:$V,MATCH($A6,Base!$A:$A,0)),0))) -> 0
A7: =+'Valo FX'!A8 -> 5 | B7: =-'Valo FX'!T8 -> -1613.0553 | C7: =IF(C$1<INDEX('Valo FX'!$Q:$Q,MATCH($A7,'Valo FX'!$A:$A,0)),0,IF(C$1<INDEX('Valo FX'!$R:$R,MATCH($A7,'Valo FX'!$A:$A,0)),INDEX(Base!$U:$U,MATCH($A7,Base!$A:$A,0)),IF(C$1=INDEX('Valo FX'!$R:$R,MATCH($A7,'Valo FX'!$A:$A,0)),INDEX(Base!$V:$V,MATCH($A7,Base!$A:$A,0)),0))) -> 0 | D7: =IF(D$1<INDEX('Valo FX'!$Q:$Q,MATCH($A7,'Valo FX'!$A:$A,0)),0,IF(D$1<INDEX('Valo FX'!$R:$R,MATCH($A7,'Valo FX'!$A:$A,0)),INDEX(Base!$U:$U,MATCH($A7,Base!$A:$A,0)),IF(D$1=INDEX('Valo FX'!$R:$R,MATCH($A7,'Valo FX'!$A:$A,0)),INDEX(Base!$V:$V,MATCH($A7,Base!$A:$A,0)),0))) -> 0 | E7: =IF(E$1<INDEX('Valo FX'!$Q:$Q,MATCH($A7,'Valo FX'!$A:$A,0)),0,IF(E$1<INDEX('Valo FX'!$R:$R,MATCH($A7,'Valo FX'!$A:$A,0)),INDEX(Base!$U:$U,MATCH($A7,Base!$A:$A,0)),IF(E$1=INDEX('Valo FX'!$R:$R,MATCH($A7,'Valo FX'!$A:$A,0)),INDEX(Base!$V:$V,MATCH($A7,Base!$A:$A,0)),0))) -> 0 | F7: =IF(F$1<INDEX('Valo FX'!$Q:$Q,MATCH($A7,'Valo FX'!$A:$A,0)),0,IF(F$1<INDEX('Valo FX'!$R:$R,MATCH($A7,'Valo FX'!$A:$A,0)),INDEX(Base!$U:$U,MATCH($A7,Base!$A:$A,0)),IF(F$1=INDEX('Valo FX'!$R:$R,MATCH($A7,'Valo FX'!$A:$A,0)),INDEX(Base!$V:$V,MATCH($A7,Base!$A:$A,0)),0))) -> 0 | G7: =IF(G$1<INDEX('Valo FX'!$Q:$Q,MATCH($A7,'Valo FX'!$A:$A,0)),0,IF(G$1<INDEX('Valo FX'!$R:$R,MATCH($A7,'Valo FX'!$A:$A,0)),INDEX(Base!$U:$U,MATCH($A7,Base!$A:$A,0)),IF(G$1=INDEX('Valo FX'!$R:$R,MATCH($A7,'Valo FX'!$A:$A,0)),INDEX(Base!$V:$V,MATCH($A7,Base!$A:$A,0)),0))) -> 0 | H7: =IF(H$1<INDEX('Valo FX'!$Q:$Q,MATCH($A7,'Valo FX'!$A:$A,0)),0,IF(H$1<INDEX('Valo FX'!$R:$R,MATCH($A7,'Valo FX'!$A:$A,0)),INDEX(Base!$U:$U,MATCH($A7,Base!$A:$A,0)),IF(H$1=INDEX('Valo FX'!$R:$R,MATCH($A7,'Valo FX'!$A:$A,0)),INDEX(Base!$V:$V,MATCH($A7,Base!$A:$A,0)),0))) -> 0 | I7: =IF(I$1<INDEX('Valo FX'!$Q:$Q,MATCH($A7,'Valo FX'!$A:$A,0)),0,IF(I$1<INDEX('Valo FX'!$R:$R,MATCH($A7,'Valo FX'!$A:$A,0)),INDEX(Base!$U:$U,MATCH($A7,Base!$A:$A,0)),IF(I$1=INDEX('Valo FX'!$R:$R,MATCH($A7,'Valo FX'!$A:$A,0)),INDEX(Base!$V:$V,MATCH($A7,Base!$A:$A,0)),0))) -> 10.98688 | J7: =IF(J$1<INDEX('Valo FX'!$Q:$Q,MATCH($A7,'Valo FX'!$A:$A,0)),0,IF(J$1<INDEX('Valo FX'!$R:$R,MATCH($A7,'Valo FX'!$A:$A,0)),INDEX(Base!$U:$U,MATCH($A7,Base!$A:$A,0)),IF(J$1=INDEX('Valo FX'!$R:$R,MATCH($A7,'Valo FX'!$A:$A,0)),INDEX(Base!$V:$V,MATCH($A7,Base!$A:$A,0)),0))) -> 10.98688 | ... MY7: =IF(MY$1<INDEX('Valo FX'!$Q:$Q,MATCH($A7,'Valo FX'!$A:$A,0)),0,IF(MY$1<INDEX('Valo FX'!$R:$R,MATCH($A7,'Valo FX'!$A:$A,0)),INDEX(Base!$U:$U,MATCH($A7,Base!$A:$A,0)),IF(MY$1=INDEX('Valo FX'!$R:$R,MATCH($A7,'Valo FX'!$A:$A,0)),INDEX(Base!$V:$V,MATCH($A7,Base!$A:$A,0)),0))) -> 11.27858
A8: =+'Valo FX'!A9 -> 6 | B8: =-'Valo FX'!T9 -> -1723.2178 | C8: =IF(C$1<INDEX('Valo FX'!$Q:$Q,MATCH($A8,'Valo FX'!$A:$A,0)),0,IF(C$1<INDEX('Valo FX'!$R:$R,MATCH($A8,'Valo FX'!$A:$A,0)),INDEX(Base!$U:$U,MATCH($A8,Base!$A:$A,0)),IF(C$1=INDEX('Valo FX'!$R:$R,MATCH($A8,'Valo FX'!$A:$A,0)),INDEX(Base!$V:$V,MATCH($A8,Base!$A:$A,0)),0))) -> 0 | D8: =IF(D$1<INDEX('Valo FX'!$Q:$Q,MATCH($A8,'Valo FX'!$A:$A,0)),0,IF(D$1<INDEX('Valo FX'!$R:$R,MATCH($A8,'Valo FX'!$A:$A,0)),INDEX(Base!$U:$U,MATCH($A8,Base!$A:$A,0)),IF(D$1=INDEX('Valo FX'!$R:$R,MATCH($A8,'Valo FX'!$A:$A,0)),INDEX(Base!$V:$V,MATCH($A8,Base!$A:$A,0)),0))) -> 0 | E8: =IF(E$1<INDEX('Valo FX'!$Q:$Q,MATCH($A8,'Valo FX'!$A:$A,0)),0,IF(E$1<INDEX('Valo FX'!$R:$R,MATCH($A8,'Valo FX'!$A:$A,0)),INDEX(Base!$U:$U,MATCH($A8,Base!$A:$A,0)),IF(E$1=INDEX('Valo FX'!$R:$R,MATCH($A8,'Valo FX'!$A:$A,0)),INDEX(Base!$V:$V,MATCH($A8,Base!$A:$A,0)),0))) -> 0 | F8: =IF(F$1<INDEX('Valo FX'!$Q:$Q,MATCH($A8,'Valo FX'!$A:$A,0)),0,IF(F$1<INDEX('Valo FX'!$R:$R,MATCH($A8,'Valo FX'!$A:$A,0)),INDEX(Base!$U:$U,MATCH($A8,Base!$A:$A,0)),IF(F$1=INDEX('Valo FX'!$R:$R,MATCH($A8,'Valo FX'!$A:$A,0)),INDEX(Base!$V:$V,MATCH($A8,Base!$A:$A,0)),0))) -> 0 | G8: =IF(G$1<INDEX('Valo FX'!$Q:$Q,MATCH($A8,'Valo FX'!$A:$A,0)),0,IF(G$1<INDEX('Valo FX'!$R:$R,MATCH($A8,'Valo FX'!$A:$A,0)),INDEX(Base!$U:$U,MATCH($A8,Base!$A:$A,0)),IF(G$1=INDEX('Valo FX'!$R:$R,MATCH($A8,'Valo FX'!$A:$A,0)),INDEX(Base!$V:$V,MATCH($A8,Base!$A:$A,0)),0))) -> 0 | H8: =IF(H$1<INDEX('Valo FX'!$Q:$Q,MATCH($A8,'Valo FX'!$A:$A,0)),0,IF(H$1<INDEX('Valo FX'!$R:$R,MATCH($A8,'Valo FX'!$A:$A,0)),INDEX(Base!$U:$U,MATCH($A8,Base!$A:$A,0)),IF(H$1=INDEX('Valo FX'!$R:$R,MATCH($A8,'Valo FX'!$A:$A,0)),INDEX(Base!$V:$V,MATCH($A8,Base!$A:$A,0)),0))) -> 0 | I8: =IF(I$1<INDEX('Valo FX'!$Q:$Q,MATCH($A8,'Valo FX'!$A:$A,0)),0,IF(I$1<INDEX('Valo FX'!$R:$R,MATCH($A8,'Valo FX'!$A:$A,0)),INDEX(Base!$U:$U,MATCH($A8,Base!$A:$A,0)),IF(I$1=INDEX('Valo FX'!$R:$R,MATCH($A8,'Valo FX'!$A:$A,0)),INDEX(Base!$V:$V,MATCH($A8,Base!$A:$A,0)),0))) -> 12.508353 | J8: =IF(J$1<INDEX('Valo FX'!$Q:$Q,MATCH($A8,'Valo FX'!$A:$A,0)),0,IF(J$1<INDEX('Valo FX'!$R:$R,MATCH($A8,'Valo FX'!$A:$A,0)),INDEX(Base!$U:$U,MATCH($A8,Base!$A:$A,0)),IF(J$1=INDEX('Valo FX'!$R:$R,MATCH($A8,'Valo FX'!$A:$A,0)),INDEX(Base!$V:$V,MATCH($A8,Base!$A:$A,0)),0))) -> 12.508353 | ... MY8: =IF(MY$1<INDEX('Valo FX'!$Q:$Q,MATCH($A8,'Valo FX'!$A:$A,0)),0,IF(MY$1<INDEX('Valo FX'!$R:$R,MATCH($A8,'Valo FX'!$A:$A,0)),INDEX(Base!$U:$U,MATCH($A8,Base!$A:$A,0)),IF(MY$1=INDEX('Valo FX'!$R:$R,MATCH($A8,'Valo FX'!$A:$A,0)),INDEX(Base!$V:$V,MATCH($A8,Base!$A:$A,0)),0))) -> 0
A9: =+'Valo FX'!A10 -> 7 | B9: =-'Valo FX'!T10 -> -1695.5741 | C9: =IF(C$1<INDEX('Valo FX'!$Q:$Q,MATCH($A9,'Valo FX'!$A:$A,0)),0,IF(C$1<INDEX('Valo FX'!$R:$R,MATCH($A9,'Valo FX'!$A:$A,0)),INDEX(Base!$U:$U,MATCH($A9,Base!$A:$A,0)),IF(C$1=INDEX('Valo FX'!$R:$R,MATCH($A9,'Valo FX'!$A:$A,0)),INDEX(Base!$V:$V,MATCH($A9,Base!$A:$A,0)),0))) -> 0 | D9: =IF(D$1<INDEX('Valo FX'!$Q:$Q,MATCH($A9,'Valo FX'!$A:$A,0)),0,IF(D$1<INDEX('Valo FX'!$R:$R,MATCH($A9,'Valo FX'!$A:$A,0)),INDEX(Base!$U:$U,MATCH($A9,Base!$A:$A,0)),IF(D$1=INDEX('Valo FX'!$R:$R,MATCH($A9,'Valo FX'!$A:$A,0)),INDEX(Base!$V:$V,MATCH($A9,Base!$A:$A,0)),0))) -> 0 | E9: =IF(E$1<INDEX('Valo FX'!$Q:$Q,MATCH($A9,'Valo FX'!$A:$A,0)),0,IF(E$1<INDEX('Valo FX'!$R:$R,MATCH($A9,'Valo FX'!$A:$A,0)),INDEX(Base!$U:$U,MATCH($A9,Base!$A:$A,0)),IF(E$1=INDEX('Valo FX'!$R:$R,MATCH($A9,'Valo FX'!$A:$A,0)),INDEX(Base!$V:$V,MATCH($A9,Base!$A:$A,0)),0))) -> 0 | F9: =IF(F$1<INDEX('Valo FX'!$Q:$Q,MATCH($A9,'Valo FX'!$A:$A,0)),0,IF(F$1<INDEX('Valo FX'!$R:$R,MATCH($A9,'Valo FX'!$A:$A,0)),INDEX(Base!$U:$U,MATCH($A9,Base!$A:$A,0)),IF(F$1=INDEX('Valo FX'!$R:$R,MATCH($A9,'Valo FX'!$A:$A,0)),INDEX(Base!$V:$V,MATCH($A9,Base!$A:$A,0)),0))) -> 0 | G9: =IF(G$1<INDEX('Valo FX'!$Q:$Q,MATCH($A9,'Valo FX'!$A:$A,0)),0,IF(G$1<INDEX('Valo FX'!$R:$R,MATCH($A9,'Valo FX'!$A:$A,0)),INDEX(Base!$U:$U,MATCH($A9,Base!$A:$A,0)),IF(G$1=INDEX('Valo FX'!$R:$R,MATCH($A9,'Valo FX'!$A:$A,0)),INDEX(Base!$V:$V,MATCH($A9,Base!$A:$A,0)),0))) -> 0 | H9: =IF(H$1<INDEX('Valo FX'!$Q:$Q,MATCH($A9,'Valo FX'!$A:$A,0)),0,IF(H$1<INDEX('Valo FX'!$R:$R,MATCH($A9,'Valo FX'!$A:$A,0)),INDEX(Base!$U:$U,MATCH($A9,Base!$A:$A,0)),IF(H$1=INDEX('Valo FX'!$R:$R,MATCH($A9,'Valo FX'!$A:$A,0)),INDEX(Base!$V:$V,MATCH($A9,Base!$A:$A,0)),0))) -> 0 | I9: =IF(I$1<INDEX('Valo FX'!$Q:$Q,MATCH($A9,'Valo FX'!$A:$A,0)),0,IF(I$1<INDEX('Valo FX'!$R:$R,MATCH($A9,'Valo FX'!$A:$A,0)),INDEX(Base!$U:$U,MATCH($A9,Base!$A:$A,0)),IF(I$1=INDEX('Valo FX'!$R:$R,MATCH($A9,'Valo FX'!$A:$A,0)),INDEX(Base!$V:$V,MATCH($A9,Base!$A:$A,0)),0))) -> 11.548934 | J9: =IF(J$1<INDEX('Valo FX'!$Q:$Q,MATCH($A9,'Valo FX'!$A:$A,0)),0,IF(J$1<INDEX('Valo FX'!$R:$R,MATCH($A9,'Valo FX'!$A:$A,0)),INDEX(Base!$U:$U,MATCH($A9,Base!$A:$A,0)),IF(J$1=INDEX('Valo FX'!$R:$R,MATCH($A9,'Valo FX'!$A:$A,0)),INDEX(Base!$V:$V,MATCH($A9,Base!$A:$A,0)),0))) -> 11.548934 | ... MY9: =IF(MY$1<INDEX('Valo FX'!$Q:$Q,MATCH($A9,'Valo FX'!$A:$A,0)),0,IF(MY$1<INDEX('Valo FX'!$R:$R,MATCH($A9,'Valo FX'!$A:$A,0)),INDEX(Base!$U:$U,MATCH($A9,Base!$A:$A,0)),IF(MY$1=INDEX('Valo FX'!$R:$R,MATCH($A9,'Valo FX'!$A:$A,0)),INDEX(Base!$V:$V,MATCH($A9,Base!$A:$A,0)),0))) -> 11.855557
A10: =+'Valo FX'!A11 -> 8 | B10: =-'Valo FX'!T11 -> -812.31826 | C10: =IF(C$1<INDEX('Valo FX'!$Q:$Q,MATCH($A10,'Valo FX'!$A:$A,0)),0,IF(C$1<INDEX('Valo FX'!$R:$R,MATCH($A10,'Valo FX'!$A:$A,0)),INDEX(Base!$U:$U,MATCH($A10,Base!$A:$A,0)),IF(C$1=INDEX('Valo FX'!$R:$R,MATCH($A10,'Valo FX'!$A:$A,0)),INDEX(Base!$V:$V,MATCH($A10,Base!$A:$A,0)),0))) -> 0 | D10: =IF(D$1<INDEX('Valo FX'!$Q:$Q,MATCH($A10,'Valo FX'!$A:$A,0)),0,IF(D$1<INDEX('Valo FX'!$R:$R,MATCH($A10,'Valo FX'!$A:$A,0)),INDEX(Base!$U:$U,MATCH($A10,Base!$A:$A,0)),IF(D$1=INDEX('Valo FX'!$R:$R,MATCH($A10,'Valo FX'!$A:$A,0)),INDEX(Base!$V:$V,MATCH($A10,Base!$A:$A,0)),0))) -> 0 | E10: =IF(E$1<INDEX('Valo FX'!$Q:$Q,MATCH($A10,'Valo FX'!$A:$A,0)),0,IF(E$1<INDEX('Valo FX'!$R:$R,MATCH($A10,'Valo FX'!$A:$A,0)),INDEX(Base!$U:$U,MATCH($A10,Base!$A:$A,0)),IF(E$1=INDEX('Valo FX'!$R:$R,MATCH($A10,'Valo FX'!$A:$A,0)),INDEX(Base!$V:$V,MATCH($A10,Base!$A:$A,0)),0))) -> 0 | F10: =IF(F$1<INDEX('Valo FX'!$Q:$Q,MATCH($A10,'Valo FX'!$A:$A,0)),0,IF(F$1<INDEX('Valo FX'!$R:$R,MATCH($A10,'Valo FX'!$A:$A,0)),INDEX(Base!$U:$U,MATCH($A10,Base!$A:$A,0)),IF(F$1=INDEX('Valo FX'!$R:$R,MATCH($A10,'Valo FX'!$A:$A,0)),INDEX(Base!$V:$V,MATCH($A10,Base!$A:$A,0)),0))) -> 0 | G10: =IF(G$1<INDEX('Valo FX'!$Q:$Q,MATCH($A10,'Valo FX'!$A:$A,0)),0,IF(G$1<INDEX('Valo FX'!$R:$R,MATCH($A10,'Valo FX'!$A:$A,0)),INDEX(Base!$U:$U,MATCH($A10,Base!$A:$A,0)),IF(G$1=INDEX('Valo FX'!$R:$R,MATCH($A10,'Valo FX'!$A:$A,0)),INDEX(Base!$V:$V,MATCH($A10,Base!$A:$A,0)),0))) -> 0 | H10: =IF(H$1<INDEX('Valo FX'!$Q:$Q,MATCH($A10,'Valo FX'!$A:$A,0)),0,IF(H$1<INDEX('Valo FX'!$R:$R,MATCH($A10,'Valo FX'!$A:$A,0)),INDEX(Base!$U:$U,MATCH($A10,Base!$A:$A,0)),IF(H$1=INDEX('Valo FX'!$R:$R,MATCH($A10,'Valo FX'!$A:$A,0)),INDEX(Base!$V:$V,MATCH($A10,Base!$A:$A,0)),0))) -> 0 | I10: =IF(I$1<INDEX('Valo FX'!$Q:$Q,MATCH($A10,'Valo FX'!$A:$A,0)),0,IF(I$1<INDEX('Valo FX'!$R:$R,MATCH($A10,'Valo FX'!$A:$A,0)),INDEX(Base!$U:$U,MATCH($A10,Base!$A:$A,0)),IF(I$1=INDEX('Valo FX'!$R:$R,MATCH($A10,'Valo FX'!$A:$A,0)),INDEX(Base!$V:$V,MATCH($A10,Base!$A:$A,0)),0))) -> 5.532881 | J10: =IF(J$1<INDEX('Valo FX'!$Q:$Q,MATCH($A10,'Valo FX'!$A:$A,0)),0,IF(J$1<INDEX('Valo FX'!$R:$R,MATCH($A10,'Valo FX'!$A:$A,0)),INDEX(Base!$U:$U,MATCH($A10,Base!$A:$A,0)),IF(J$1=INDEX('Valo FX'!$R:$R,MATCH($A10,'Valo FX'!$A:$A,0)),INDEX(Base!$V:$V,MATCH($A10,Base!$A:$A,0)),0))) -> 5.532881 | ... MY10: =IF(MY$1<INDEX('Valo FX'!$Q:$Q,MATCH($A10,'Valo FX'!$A:$A,0)),0,IF(MY$1<INDEX('Valo FX'!$R:$R,MATCH($A10,'Valo FX'!$A:$A,0)),INDEX(Base!$U:$U,MATCH($A10,Base!$A:$A,0)),IF(MY$1=INDEX('Valo FX'!$R:$R,MATCH($A10,'Valo FX'!$A:$A,0)),INDEX(Base!$V:$V,MATCH($A10,Base!$A:$A,0)),0))) -> 5.679779
