Workbook

Sheet Base
A1: Nº | B1: N° Operación CMF | C1: Rut | D1: RUT | E1: DV | F1: Apellido paterno | G1: Apellido materno | H1: Nombres | I1: Género | J1: Segmento | K1: Pie | L1: Precio venta propiedad | M1: Subsidio | N1: Valor de tasación | O1: Tasa anual de emisión | P1: Tasa mensual de emisión | Q1: Plazo en meses | R1: Meses de gracia | S1: LTV | T1: Monto otorgado (UF) | U1: Valor cuota (UF) | V1: Valor última cuota (UF) | W1: Spread | X1: Tasa anual de endoso | Y1: Tasa mensual de endoso | Z1: Fecha de suscripción | AA1: Período primer aporte | AB1: Fecha de endoso | AC1: Fecha primer aporte a endosar | AD1: Fecha último aporte | AE1: Número de cuotas a endosar | AF1: VAN fecha endoso | AG1: Dirección | AH1: Comuna | AI1: Ciudad | AJ1: Region | AK1: Notaría | AL1: Dividendo/ Renta | AM1: Carga Financiera
A2: 1 | B2: 202401300028A033 | C2: 18028529-6 | D2: =LEFT(C2,LEN(C2)-2) -> 18028529 | E2: =RIGHT(C2,1) -> 6 | F2: Bobadilla | G2: Lopez | H2: Juan Pablo | I2: Masculino | J2: Subsidio | K2: 455 | L2: 2200 | M2: 375 | N2: 2400 | O2: 0.0783 | P2: 0.006301918 | Q2: 360 | R2: 5 | S2: 0.79318182 | T2: 1745 | U2: 12.71407 | V2: 13.752345 | W2: -0.004 | X2: 0.0743 | Y2: 0.0059903111 | Z2: 45321 | AA2: 45514 | AB2: 45351 | AC2: 45514 | AD2: 56290 | AE2: 355 | AF2: 1819.2749 | AG2: Camino La Vara 02600 , Edificio 3, Piso 2, Departamento 211, Estacionamiento 61 Uso y Goce | AH2: San Bernardo | AI2: Maipo | AJ2: Región Metropolitana de Santiago | AK2: María Soledad Lascar Merino | AL2: 0.25258541 | AM2: 0.48488599 | AN2: 5076 | AO2: OK
A3: 2 | B3: 202401310029A033 | C3: 17540548-8 | D3: =LEFT(C3,LEN(C3)-2) -> 17540548 | E3: =RIGHT(C3,1) -> 8 | F3: Carrillo | G3: Alarcon | H3: Francisco Javier | I3: Masculino | J3: Subsidio | K3: 440 | L3: 2200 | M3: 325 | N3: 2650 | O3: 0.0783 | P3: 0.006301918 | Q3: 360 | R3: 5 | S3: 0.8 | T3: 1760 | U3: 12.82336 | V3: 13.87056 | W3: -0.004 | X3: 0.0743 | Y3: 0.0059903111 | Z3: 45322 | AA3: 45514 | AB3: 45351 | AC3: 45514 | AD3: 56290 | AE3: 355 | AF3: 1835.0201 | AG3: Camino Segunda Faja Al Volcán 1260, Edificio ALLIPEN, Piso 4, Departamento 403, Estacionamiento 92 Uso y Goce | AH3: Villarrica | AI3: Cautín | AJ3: Región de La Araucanía | AK3: Elena Rosa Leyton Carvajal | AL3: 0.28239147 | AM3: 0.48306333 | AN3: 394 | AO3: OK
A4: 3 | B4: 202401310030A033 | C4: 18465199-8 | D4: =LEFT(C4,LEN(C4)-2) -> 18465199 | E4: =RIGHT(C4,1) -> 8 | F4: Mañan | G4: Valenzuela | H4: Vicente Tomas | I4: Masculino | J4: Subsidio | K4: 715 | L4: 2200 | M4: 625 | N4: 2200 | O4: 0.0783 | P4: 0.006301918 | Q4: 216 | R4: 5 | S4: 0.675 | T4: 1485 | U4: 13.15116 | V4: 12.92544 | W4: -0.004 | X4: 0.0743 | Y4: 0.0059903111 | Z4: 45322 | AA4: 45514 | AB4: 45351 | AC4: 45514 | AD4: 51907 | AE4: 211 | AF4: 1532.1686 | AG4: Avenida Santa Rosa 13240, Torre 3, Piso 1, Departamento 234 | AH4: La Pintana | AI4: Santiago | AJ4: Región Metropolitana de Santiago | AK4: María Soledad Lascar Merino | AL4: 0.13614764 | AM4: 0.27305764 | AN4: 5280 | AO4: OK
A5: 4 | B5: 202401310034A033 | C5: 15365153-1 | D5: =LEFT(C5,LEN(C5)-2) -> 15365153 | E5: =RIGHT(C5,1) -> 1 | F5: Jelves | G5: Sanchez | H5: Sebastian Andres | I5: Masculino | J5: Subsidio | K5: 893.66 | L5: 2400 | M5: 700 | N5: 2600 | O5: 0.0783 | P5: 0.006301918 | Q5: 360 | R5: 5 | S5: 0.62764167 | T5: 1506.34 | U5: 10.975193 | V5: 11.871466 | W5: -0.004 | X5: 0.0743 | Y5: 0.0059903111 | Z5: 45322 | AA5: 45514 | AB5: 45351 | AC5: 45514 | AD5: 56290 | AE5: 355 | AF5: 1571.6464 | AG5: Calle Miguel Campino 647, Mz D, Lote 5 | AH5: Paine | AI5: Maipo | AJ5: Región Metropolitana de Santiago | AK5: Wladimir Schramm López | AL5: 0.40079904 | AM5: 0.42389362 | AN5: 10574 | AO5: OK
A6: 5 | B6: 202401310036A033 | C6: 18187808-8 | D6: =LEFT(C6,LEN(C6)-2) -> 18187808 | E6: =RIGHT(C6,1) -> 8 | F6: Carvajal | G6: Guajardo | H6: Danahe Estefani | I6: Femenino | J6: Subsidio | K6: 780 | L6: 2065 | M6: 700 | N6: 2440 | O6: 0.0783 | P6: 0.006301918 | Q6: 360 | R6: 5 | S6: 0.62227603 | T6: 1285 | U6: 9.36251 | V6: 10.127085 | W6: -0.004 | X6: 0.0743 | Y6: 0.0059903111 | Z6: 45322 | AA6: 45514 | AB6: 45351 | AC6: 45514 | AD6: 56290 | AE6: 355 | AF6: 1339.7655 | AG6: Calle Del Toro 658, Mz D, Lote 33 | AH6: Paine | AI6: Maipo | AJ6: Región Metropolitana de Santiago | AK6: Wladimir Schramm López | AL6: 0.37717378 | AM6: 0.39792269 | AN6: 10563 | AO6: OK
A7: 6 | B7: 202401250039A033 | C7: 18245649-7 | D7: =LEFT(C7,LEN(C7)-2) -> 18245649 | E7: =RIGHT(C7,1) -> 7 | F7: Acevedo | G7: Monje | H7: Barbara Viviana | I7: Femenino | J7: Subsidio | K7: 494.87 | L7: 1400 | M7: 450 | N7: 1400 | O7: 0.0783 | P7: 0.006301918 | Q7: 180 | R7: 5 | S7: 0.64652143 | T7: 905.13 | U7: 8.825923 | V7: 8.777046 | W7: -0.004 | X7: 0.0743 | Y7: 0.0059903111 | Z7: 45316 | AA7: 45514 | AB7: 45351 | AC7: 45514 | AD7: 50811 | AE7: 175 | AF7: 931.14903 | AG7: Camino La Vara 02600, Torre 2, Piso 1, Departamento 101 | AH7: San Bernardo | AI7: Maipo | AJ7: Región Metropolitana de Santiago | AK7: María Soledad Lascar Merino | AL7: 0.41557874 | AM7: 0.4281181 | AN7: 4338 | AO7: OK
A8: 7 | B8: 202401310041A033 | C8: 15162947-4 | D8: =LEFT(C8,LEN(C8)-2) -> 15162947 | E8: =RIGHT(C8,1) -> 4 | F8: Palma | G8: Ponce | H8: Carola Del Carmen | I8: Femenino | J8: Subsidio | K8: 561.42 | L8: 1400 | M8: 500 | N8: 1800 | O8: 0.0783 | P8: 0.006301918 | Q8: 360 | R8: 5 | S8: 0.59898571 | T8: 838.58 | U8: 6.109894 | V8: 6.608849 | W8: -0.004 | X8: 0.0743 | Y8: 0.0059903111 | Z8: 45322 | AA8: 45514 | AB8: 45351 | AC8: 45514 | AD8: 56290 | AE8: 355 | AF8: 874.56881 | AG8: Rio Viejo 1123, Torre A, Piso 4, Departamento 407 A | AH8: Chillán | AI8: Diguillín | AJ8: Región de Ñuble | AK8: Luis Alvarez Diaz | AL8: 0.39962091 | AM8: 0.42110488 | AN8: 423 | AO8: OK
A9: 8 | B9: 202401310046A033 | C9: 16666807-7 | D9: =LEFT(C9,LEN(C9)-2) -> 16666807 | E9: =RIGHT(C9,1) -> 7 | F9: Acuña | G9: Mesías | H9: Kevin Joel | I9: Masculino | J9: Subsidio | K9: 979.93 | L9: 2325 | M9: 700 | N9: 2600 | O9: 0.0783 | P9: 0.006301918 | Q9: 144 | R9: 5 | S9: 0.57852473 | T9: 1345.07 | U9: 15.019052 | V9: 15.029812 | W9: -0.004 | X9: 0.0743 | Y9: 0.0059903111 | Z9: 45322 | AA9: 45514 | AB9: 45351 | AC9: 45514 | AD9: 49715 | AE9: 139 | AF9: 1377.8831 | AG9: Pasaje Copiapó Norte 071, Mz B, Lote 50 | AH9: Paine | AI9: Maipo | AJ9: Región Metropolitana de Santiago | AK9: Wladimir Schramm López | AL9: 0.37834186 | AM9: 0.40010103 | AN9: 10647 | AO9: OK
A10: 9 | B10: 202401310053A033 | C10: 14336994-3 | D10: =LEFT(C10,LEN(C10)-2) -> 14336994 | E10: =RIGHT(C10,1) -> 3 | F10: Valdes | G10: Molina | H10: Isabel Damari | I10: Femenino | J10: Subsidio | K10: 830 | L10: 1725 | M10: 750 | N10: 1725 | O10: 0.0783 | P10: 0.006301918 | Q10: 312 | R10: 5 | S10: 0.51884058 | T10: 895 | U10: 6.810055 | V10: 6.826165 | W10: -0.004 | X10: 0.0743 | Y10: 0.0059903111 | Z10: 45322 | AA10: 45514 | AB10: 45351 | AC10: 45514 | AD10: 54829 | AE10: 307 | AF10: 930.57378 | AG10: Pasaje Juan Vercellino Reginato 987, Mz E, Lote 9 | AH10: Rengo | AI10: Cachapoal | AJ10: Región del Libertador General Bernardo O'Higgins | AK10: Carla Silva Acharan | AL10: 0.2319673 | AM10: 0.25290877 | AN10: 280 | AO10: OK
A11: 10 | B11: 202401310054A033 | C11: 19580720-5 | D11: =LEFT(C11,LEN(C11)-2) -> 19580720 | E11: =RIGHT(C11,1) -> 5 | F11: Gonzalez | G11: Jaque | H11: Tabita Del Pilar | I11: Femenino | J11: Subsidio | K11: 830 | L11: 1725 | M11: 750 | N11: 1725 | O11: 0.0783 | P11: 0.006301918 | Q11: 228 | R11: 5 | S11: 0.51884058 | T11: 895 | U11: 7.722955 | V11: 7.72743 | W11: -0.004 | X11: 0.0743 | Y11: 0.0059903111 | Z11: 45322 | AA11: 45514 | AB11: 45351 | AC11: 45514 | AD11: 52272 | AE11: 223 | AF11: 924.16029 | AG11: Pasaje Elena Sanhueza Fajardo 794, Mz C, Lote 1 | AH11: Rengo | AI11: Cachapoal | AJ11: Región del Libertador General Bernardo O'Higgins | AK11: Carla Silva Acharan | AL11: 0.21381348 | AM11: 0.24493721 | AN11: 288 | AO11: OK
A12: 11 | B12: 202401310063A033 | C12: 14349421-7 | D12: =LEFT(C12,LEN(C12)-2) -> 14349421 | E12: =RIGHT(C12,1) -> 7 | F12: Ormeno | G12: Salazar | H12: Gino Rexner | I12: Masculino | J12: Subsidio | K12: 605 | L12: 2200 | M12: 525 | N12: 2325 | O12: 0.0783 | P12: 0.006301918 | Q12: 360 | R12: 5 | S12: 0.725 | T12: 1595 | U12: 11.62117 | V12: 12.570195 | W12: -0.004 | X12: 0.0743 | Y12: 0.0059903111 | Z12: 45322 | AA12: 45514 | AB12: 45351 | AC12: 45514 | AD12: 56290 | AE12: 355 | AF12: 1663.2551 | AG12: Pasaje La Cumbre 1 2505, Mz 8, Lote 4 | AH12: Los Ángeles | AI12: Biobío | AJ12: Región del Biobío | AK12: Maria Antonieta Carrillo Flores | AL12: 0.43872737 | AM12: 0.48266432 | AN12: 244 | AO12: OK
A13: 12 | B13: 202401310057A033 | C13: 14337194-8 | D13: =LEFT(C13,LEN(C13)-2) -> 14337194 | E13: =RIGHT(C13,1) -> 8 | F13: Osorio | G13: Briones | H13: Marcela Andrea | I13: Femenino | J13: Subsidio | K13: 830 | L13: 1725 | M13: 750 | N13: 1725 | O13: 0.0783 | P13: 0.006301918 | Q13: 348 | R13: 5 | S13: 0.51884058 | T13: 895 | U13: 6.58362 | V13: 6.391195 | W13: -0.004 | X13: 0.0743 | Y13: 0.0059903111 | Z13: 45322 | AA13: 45514 | AB13: 45351 | AC13: 45514 | AD13: 55925 | AE13: 343 | AF13: 932.21409 | AG13: Pasaje Raquel Labarca Urzua 759, Mz C, Lote 9 | AH13: Rengo | AI13: Cachapoal | AJ13: Región del Libertador General Bernardo O'Higgins | AK13: Carla Silva Acharan | AL13: 0.11836401 | AM13: 0.41558002 | AN13: 285 | AO13: OK
... A35: 34 | B35: 202402260086A033 | C35: 11392169-2 | D35: =LEFT(C35,LEN(C35)-2) -> 11392169 | E35: =RIGHT(C35,1) -> 2 | F35: Donoso | G35: Valdebenito | H35: Raul Cristian | I35: Masculino | J35: Subsidio | K35: 780 | L35: 2400 | M35: 700 | N35: 2600 | O35: 0.0759 | P35: 0.0061150813 | Q35: 300 | R35: 5 | S35: 0.675 | T35: 1620 | U35: 12.2391 | V35: 12.33468 | W35: -0.004 | X35: 0.0719 | Y35: 0.0058028362 | Z35: 45348 | AA35: 45545 | AB35: 45351 | AC35: 45545 | AD35: 54492 | AE35: 295 | AF35: 1673.7345 | AG35: CALLE DEL TORO 1306 | AH35: Paine | AI35: Maipo | AJ35: Región Metropolitana de Santiago | AK35: Wladimir Schramm López | AL35: 0.30137122 | AM35: 0.5317244 | AN35: 19368 | AO35: DD OK
A36: 35 | B36: 202402220087A033 | C36: 20039829-7 | D36: =LEFT(C36,LEN(C36)-2) -> 20039829 | E36: =RIGHT(C36,1) -> 7 | F36: Medel | G36: Bustos | H36: Pablo Andres | I36: Masculino | J36: Subsidio | K36: 680 | L36: 2400 | M36: 600 | N36: 2400 | O36: 0.0759 | P36: 0.0061150813 | Q36: 360 | R36: 5 | S36: 0.71666667 | T36: 1720 | U36: 12.24984 | V36: 12.6334 | W36: -0.004 | X36: 0.0719 | Y36: 0.0058028362 | Z36: 45344 | AA36: 45545 | AB36: 45351 | AC36: 45545 | AD36: 56318 | AE36: 355 | AF36: 1784.0307 | AG36: CALLE VICTOR MANUEL SAAVEDRA CAMPOS (DIRIGENTE) 412 | AH36: Rengo | AI36: Cachapoal | AJ36: Región del Libertador General Bernardo O'Higgins | AK36: Andrés Falcón Valencia | AL36: 0.30884557 | AM36: 0.3714098 | AN36: N/A | AO36: DD OK
A37: 36 | B37: 202402260088A033 | C37: 16377478-K | D37: =LEFT(C37,LEN(C37)-2) -> 16377478 | E37: =RIGHT(C37,1) -> K | F37: Parra | G37: Gálvez | H37: Angie Marcela | I37: Femenino | J37: Subsidio | K37: 743.35 | L37: 2325 | M37: 700 | N37: 2600 | O37: 0.0759 | P37: 0.0061150813 | Q37: 360 | R37: 5 | S37: 0.68027957 | T37: 1581.65 | U37: 11.264511 | V37: 11.617219 | W37: -0.004 | X37: 0.0719 | Y37: 0.0058028362 | Z37: 45348 | AA37: 45545 | AB37: 45351 | AC37: 45545 | AD37: 56318 | AE37: 355 | AF37: 1639.8532 | AG37: PASAJE COPIAPÓ NORTE 070 | AH37: Paine | AI37: Maipo | AJ37: Región Metropolitana de Santiago | AK37: Wladimir Schramm López | AL37: 0.22315429 | AM37: 0.35014293 | AN37: 19404 | AO37: DD OK
A38: 37 | B38: 202402270089A033 | C38: 16597475-1 | D38: =LEFT(C38,LEN(C38)-2) -> 16597475 | E38: =RIGHT(C38,1) -> 1 | F38: Cortes | G38: Rodriguez | H38: Ruben Alex | I38: Masculino | J38: Subsidio | K38: 470 | L38: 2100 | M38: 375 | N38: 2100 | O38: 0.0759 | P38: 0.0061150813 | Q38: 360 | R38: 5 | S38: 0.77619048 | T38: 1630 | U38: 11.60886 | V38: 11.97235 | W38: -0.004 | X38: 0.0719 | Y38: 0.0058028362 | Z38: 45349 | AA38: 45545 | AB38: 45351 | AC38: 45545 | AD38: 56318 | AE38: 355 | AF38: 1690.8242 | AG38: Alemania 30, Edificio 3 | AH38: Viña del Mar | AI38: Valparaíso | AJ38: Región de Valparaíso | AK38: Luis Enrique Fischer Yavar | AL38: 0.25436079 | AM38: 0.35435235 | AN38: 2024 | AO38: DD OK
A39: 38 | B39: 202402270090A033 | C39: 12406726-K | D39: =LEFT(C39,LEN(C39)-2) -> 12406726 | E39: =RIGHT(C39,1) -> K | F39: Morales | G39: Sanchez | H39: Ivonne Arlette | I39: Femenino | J39: Subsidio | K39: 504 | L39: 1400 | M39: 450 | N39: 1400 | O39: 0.0759 | P39: 0.0061150813 | Q39: 336 | R39: 5 | S39: 0.64 | T39: 896 | U39: 6.514816 | V39: 6.33472 | W39: -0.004 | X39: 0.0719 | Y39: 0.0058028362 | Z39: 45349 | AA39: 45545 | AB39: 45351 | AC39: 45545 | AD39: 55588 | AE39: 331 | AF39: 927.26287 | AG39: PASAJE EXEQUIEL SANCHEZ BALMACEDA (PROFESOR) 1708 | AH39: Rengo | AI39: Cachapoal | AJ39: Región del Libertador General Bernardo O'Higgins | AK39: Andrés Falcón Valencia | AL39: 0.18231278 | AM39: 0.30271257 | AN39: N/A | AO39: DD OK
A40: 39 | B40: 202402280091A033 | C40: 18452074-5 | D40: =LEFT(C40,LEN(C40)-2) -> 18452074 | E40: =RIGHT(C40,1) -> 5 | F40: Aguilera | G40: Benedetti | H40: Natalia Pamela | I40: Femenino | J40: Subsidio | K40: 540 | L40: 1400 | M40: 500 | N40: 1400 | O40: 0.0759 | P40: 0.0061150813 | Q40: 360 | R40: 5 | S40: 0.61428571 | T40: 860 | U40: 6.12492 | V40: 6.3167 | W40: -0.004 | X40: 0.0719 | Y40: 0.0058028362 | Z40: 45350 | AA40: 45545 | AB40: 45351 | AC40: 45545 | AD40: 56318 | AE40: 355 | AF40: 891.28843 | AG40: Camino Las Rosas 518, Edificio 12 | AH40: Chillán | AI40: Diguillín | AJ40: Región de Ñuble | AK40: Luis Álvarez Diaz | AL40: 0.091882356 | AM40: 0.25231874 | AN40: 842 | AO40: Firmada
A41: 40 | B41: 202402240093A033 | C41: 20614987-6 | D41: =LEFT(C41,LEN(C41)-2) -> 20614987 | E41: =RIGHT(C41,1) -> 6 | F41: Perez | G41: Avalos | H41: Belen Del Carmen | I41: Femenino | J41: Subsidio | K41: 780 | L41: 1990 | M41: 700 | N41: 2200 | O41: 0.0759 | P41: 0.0061150813 | Q41: 360 | R41: 5 | S41: 0.6080402 | T41: 1210 | U41: 8.61762 | V41: 8.88745 | W41: -0.004 | X41: 0.0719 | Y41: 0.0058028362 | Z41: 45346 | AA41: 45545 | AB41: 45351 | AC41: 45545 | AD41: 56318 | AE41: 355 | AF41: 1255.3754 | AG41: Matta Vial 635 | AH41: San Joaquín | AI41: Santiago | AJ41: Región Metropolitana de Santiago | AK41: Pablo Martínez Loaiza | AL41: 0.26464127 | AM41: 0.50420421 | AN41: 3957 | AO41: DD OK
A42: 41 | B42: 202402270094A033 | C42: 22607181-4 | D42: =LEFT(C42,LEN(C42)-2) -> 22607181 | E42: =RIGHT(C42,1) -> 4 | F42: Lopez | G42: Tineo | H42: Hector | I42: Masculino | J42: Subsidio | K42: 680 | L42: 2400 | M42: 600 | N42: 2400 | O42: 0.0759 | P42: 0.0061150813 | Q42: 360 | R42: 5 | S42: 0.71666667 | T42: 1720 | U42: 12.24984 | V42: 12.6334 | W42: -0.004 | X42: 0.0719 | Y42: 0.0058028362 | Z42: 45349 | AA42: 45545 | AB42: 45351 | AC42: 45545 | AD42: 56318 | AE42: 355 | AF42: 1784.0307 | AG42: PASAJE AGUSTO SANCHEZ BALMACEDA (PROFESOR) 1709 | AH42: Rengo | AI42: Cachapoal | AJ42: Región del Libertador General Bernardo O'Higgins | AK42: Andrés Falcón Valencia | AL42: 0.25324608 | AM42: 0.31799542 | AN42: N/A | AO42: DD OK
A43: 42 | B43: 202402260095A033 | C43: 18916005-4 | D43: =LEFT(C43,LEN(C43)-2) -> 18916005 | E43: =RIGHT(C43,1) -> 4 | F43: Espinoza | G43: Huerta | H43: Daniela Mackarena | I43: Femenino | J43: Subsidio | K43: 505 | L43: 1870 | M43: 425 | N43: 2100 | O43: 0.0759 | P43: 0.0061150813 | Q43: 216 | R43: 5 | S43: 0.72994652 | T43: 1365 | U43: 11.890515 | V43: 11.857755 | W43: -0.004 | X43: 0.0719 | Y43: 0.0058028362 | Z43: 45348 | AA43: 45545 | AB43: 45351 | AC43: 45545 | AD43: 51935 | AE43: 211 | AF43: 1400.3211 | AG43: San Enrique 1398, Edificio 2 | AH43: Villa Alemana | AI43: Marga Marga | AJ43: Región de Valparaíso | AK43: Luis Enrique Fischer Yavar | AL43: 0.21950803 | AM43: 0.34815283 | AN43: 2019 | AO43: Firmada

Sheet Valo FX
V1: valor Creditú
I2: Monto Crédito + Cap (UF) | P2: Tasa endoso | Q2: Fecha 1er Aporte a endosar | R2: Fecha Last Aporte | S2: Fecha Corte | U2: VPN | V2: Tasa mensual de endoso | X2: Tasacion | Y2: Precio Venta/Tasación | Z2: Tasa Endoso | AA2: Monto Dividendo | AB2: Dividendo/ Renta | AC2: Carga Financiera/ Renta
A3: Nº | B3: N° Operación | C3: Apellido paterno | D3: Apellido materno | E3: Nombres | F3: Rut | G3: DV | H3: Leasing o Mutuo | J3: Subsidio | K3: Pie | L3: Valor Vivienda | M3: Morosidad | N3: Nº Cuotas | O3: Primera cuota a endosar | T3: 45361 | U3: 45351 | W3: Saldo insoluto Teórico | AD3: Dirección de la Propiedad | AE3: Codigo Comuna | AF3: Comuna
A4: =+Base!A2 -> 1 | B4: =+Base!B2 -> 202401300028A033 | C4: =+Base!F2 -> Bobadilla | D4: =+Base!G2 -> Lopez | E4: =+Base!H2 -> Juan Pablo | F4: =+Base!D2 -> 18028529 | G4: =+Base!E2 -> 6 | H4: MHE | I4: =+Base!T2 -> 1745 | J4: =+Base!M2 -> 375 | K4: =+L4-J4-I4 -> 80 | L4: =+Base!L2 -> 2200 | M4: 0 | N4: =+Base!Q2 -> 360 | O4: =+Base!R2+1 -> 6 | P4: =+XIRR('Tabla desarrollo FX'!B3:MY3,'Tabla desarrollo FX'!$B$1:$MY$1) -> 0.07403166 | Q4: =+Base!AA2 -> 45514 | R4: =+Base!AD2 -> 56290 | S4: =T3 -> 45361 | T4: =+NPV(V4,'Tabla desarrollo FX'!D3:MY3) -> 1823.765 | U4: =+Base!AF2 -> 1819.2749 | V4: =+Base!Y2 -> 0.0059903111 | X4: =+Base!N2 -> 2400 | Y4: =+U4/X4 -> 0.7580312 | Z4: =+P4-Base!O2 -> -0.00426834 | AA4: =+Base!U2 -> 12.71407 | AB4: =+Base!AL2*100 -> 25.258541 | AC4: =+Base!AM2*100 -> 48.488599 | AD4: =+Base!AG2 -> Camino La Vara 02600 , Edificio 3, Piso 2, Departamento 211, Estacionamiento 61 Uso y Goce | AE4: 4103 | AF4: =+Base!AI2 -> Maipo
A5: =+Base!A3 -> 2 | B5: =+Base!B3 -> 202401310029A033 | C5: =+Base!F3 -> Carrillo | D5: =+Base!G3 -> Alarcon | E5: =+Base!H3 -> Francisco Javier | F5: =+Base!D3 -> 17540548 | G5: =+Base!E3 -> 8 | H5: MHE | I5: =+Base!T3 -> 1760 | J5: =+Base!M3 -> 325 | K5: =+L5-J5-I5 -> 115 | L5: =+Base!L3 -> 2200 | M5: 0 | N5: =+Base!Q3 -> 360 | O5: =+Base!R3+1 -> 6 | P5: =+XIRR('Tabla desarrollo FX'!B4:MY4,'Tabla desarrollo FX'!$B$1:$MY$1) -> 0.07403166 | Q5: =+Base!AA3 -> 45514 | R5: =+Base!AD3 -> 56290 | S5: =S4 -> 45361 | T5: =+NPV(V5,'Tabla desarrollo FX'!D4:MY4) -> 1839.4421 | U5: =+Base!AF3 -> 1835.0201 | V5: =+Base!Y3 -> 0.0059903111 | X5: =+Base!N3 -> 2650 | Y5: =+U5/X5 -> 0.69246041 | Z5: =+P5-Base!O3 -> -0.00426834 | AA5: =+Base!U3 -> 12.82336 | AB5: =+Base!AL3*100 -> 28.239147 | AC5: =+Base!AM3*100 -> 48.306333 | AD5: =+Base!AG3 -> Camino Segunda Faja Al Volcán 1260, Edificio ALLIPEN, Piso 4, Departamento 403, Estacionamiento 92 Uso y Goce | AE5: 4103 | AF5: =+Base!AI3 -> Cautín
A6: =+Base!A4 -> 3 | B6: =+Base!B4 -> 202401310030A033 | C6: =+Base!F4 -> Mañan | D6: =+Base!G4 -> Valenzuela | E6: =+Base!H4 -> Vicente Tomas | F6: =+Base!D4 -> 18465199 | G6: =+Base!E4 -> 8 | H6: MHE | I6: =+Base!T4 -> 1485 | J6: =+Base!M4 -> 625 | K6: =+L6-J6-I6 -> 90 | L6: =+Base!L4 -> 2200 | M6: 0 | N6: =+Base!Q4 -> 216 | O6: =+Base!R4+1 -> 6 | P6: =+XIRR('Tabla desarrollo FX'!B5:MY5,'Tabla desarrollo FX'!$B$1:$MY$1) -> 0.073945948 | Q6: =+Base!AA4 -> 45514 | R6: =+Base!AD4 -> 51907 | S6: =S5 -> 45361 | T6: =+NPV(V6,'Tabla desarrollo FX'!D5:MY5) -> 1535.5941 | U6: =+Base!AF4 -> 1532.1686 | V6: =+Base!Y4 -> 0.0059903111 | X6: =+Base!N4 -> 2200 | Y6: =+U6/X6 -> 0.69644028 | Z6: =+P6-Base!O4 -> -0.0043540515 | AA6: =+Base!U4 -> 13.15116 | AB6: =+Base!AL4*100 -> 13.614764 | AC6: =+Base!AM4*100 -> 27.305764 | AD6: =+Base!AG4 -> Avenida Santa Rosa 13240, Torre 3, Piso 1, Departamento 234 | AE6: 4103 | AF6: =+Base!AI4 -> Santiago
A7: =+Base!A5 -> 4 | B7: =+Base!B5 -> 202401310034A033 | C7: =+Base!F5 -> Jelves | D7: =+Base!G5 -> Sanchez | E7: =+Base!H5 -> Sebastian Andres | F7: =+Base!D5 -> 15365153 | G7: =+Base!E5 -> 1 | H7: MHE | I7: =+Base!T5 -> 1506.34 | J7: =+Base!M5 -> 700 | K7: =+L7-J7-I7 -> 193.66 | L7: =+Base!L5 -> 2400 | M7: 0 | N7: =+Base!Q5 -> 360 | O7: =+Base!R5+1 -> 6 | P7: =+XIRR('Tabla desarrollo FX'!B6:MY6,'Tabla desarrollo FX'!$B$1:$MY$1) -> 0.07403166 | Q7: =+Base!AA5 -> 45514 | R7: =+Base!AD5 -> 56290 | S7: =S6 -> 45361 | T7: =+NPV(V7,'Tabla desarrollo FX'!D6:MY6) -> 1574.3324 | U7: =+Base!AF5 -> 1571.6464 | V7: =+Base!Y5 -> 0.0059903111 | X7: =+Base!N5 -> 2600 | Y7: =+U7/X7 -> 0.60447938 | Z7: =+P7-Base!O5 -> -0.00426834 | AA7: =+Base!U5 -> 10.975193 | AB7: =+Base!AL5*100 -> 40.079904 | AC7: =+Base!AM5*100 -> 42.389362 | AD7: =+Base!AG5 -> Calle Miguel Campino 647, Mz D, Lote 5 | AE7: 4103 | AF7: =+Base!AI5 -> Maipo
A8: =+Base!A6 -> 5 | B8: =+Base!B6 -> 202401310036A033 | C8: =+Base!F6 -> Carvajal | D8: =+Base!G6 -> Guajardo | E8: =+Base!H6 -> Danahe Estefani | F8: =+Base!D6 -> 18187808 | G8: =+Base!E6 -> 8 | H8: MHE | I8: =+Base!T6 -> 1285 | J8: =+Base!M6 -> 700 | K8: =+L8-J8-I8 -> 80 | L8: =+Base!L6 -> 2065 | M8: 0 | N8: =+Base!Q6 -> 360 | O8: =+Base!R6+1 -> 6 | P8: =+XIRR('Tabla desarrollo FX'!B7:MY7,'Tabla desarrollo FX'!$B$1:$MY$1) -> 0.07403166 | Q8: =+Base!AA6 -> 45514 | R8: =+Base!AD6 -> 56290 | S8: =S7 -> 45361 | T8: =+NPV(V8,'Tabla desarrollo FX'!D7:MY7) -> 1343.0017 | U8: =+Base!AF6 -> 1339.7655 | V8: =+Base!Y6 -> 0.0059903111 | X8: =+Base!N6 -> 2440 | Y8: =+U8/X8 -> 0.5490842 | Z8: =+P8-Base!O6 -> -0.00426834 | AA8: =+Base!U6 -> 9.36251 | AB8: =+Base!AL6*100 -> 37.717378 | AC8: =+Base!AM6*100 -> 39.792269 | AD8: =+Base!AG6 -> Calle Del Toro 658, Mz D, Lote 33 | AE8: 4103 | AF8: =+Base!AI6 -> Maipo
A9: =+Base!A7 -> 6 | B9: =+Base!B7 -> 202401250039A033 | C9: =+Base!F7 -> Acevedo | D9: =+Base!G7 -> Monje | E9: =+Base!H7 -> Barbara Viviana | F9: =+Base!D7 -> 18245649 | G9: =+Base!E7 -> 7 | H9: MHE | I9: =+Base!T7 -> 905.13 | J9: =+Base!M7 -> 450 | K9: =+L9-J9-I9 -> 44.87 | L9: =+Base!L7 -> 1400 | M9: 0 | N9: =+Base!Q7 -> 180 | O9: =+Base!R7+1 -> 6 | P9: =+XIRR('Tabla desarrollo FX'!B8:MY8,'Tabla desarrollo FX'!$B$1:$MY$1) -> 0.073901585 | Q9: =+Base!AA7 -> 45514 | R9: =+Base!AD7 -> 50811 | S9: =S8 -> 45361 | T9: =+NPV(V9,'Tabla desarrollo FX'!D8:MY8) -> 932.71931 | U9: =+Base!AF7 -> 931.14903 | V9: =+Base!Y7 -> 0.0059903111 | X9: =+Base!N7 -> 1400 | Y9: =+U9/X9 -> 0.66510645 | Z9: =+P9-Base!O7 -> -0.0043984153 | AA9: =+Base!U7 -> 8.825923 | AB9: =+Base!AL7*100 -> 41.557874 | AC9: =+Base!AM7*100 -> 42.81181 | AD9: =+Base!AG7 -> Camino La Vara 02600, Torre 2, Piso 1, Departamento 101 | AE9: 4103 | AF9: =+Base!AI7 -> Maipo
A10: =+Base!A8 -> 7 | B10: =+Base!B8 -> 202401310041A033 | C10: =+Base!F8 -> Palma | D10: =+Base!G8 -> Ponce | E10: =+Base!H8 -> Carola Del Carmen | F10: =+Base!D8 -> 15162947 | G10: =+Base!E8 -> 4 | H10: MHE | I10: =+Base!T8 -> 838.58 | J10: =+Base!M8 -> 500 | K10: =+L10-J10-I10 -> 61.42 | L10: =+Base!L8 -> 1400 | M10: 0 | N10: =+Base!Q8 -> 360 | O10: =+Base!R8+1 -> 6 | P10: =+XIRR('Tabla desarrollo FX'!B9:MY9,'Tabla desarrollo FX'!$B$1:$MY$1) -> 0.07403166 | Q10: =+Base!AA8 -> 45514 | R10: =+Base!AD8 -> 56290 | S10: =S9 -> 45361 | T10: =+NPV(V10,'Tabla desarrollo FX'!D9:MY9) -> 876.43145 | U10: =+Base!AF8 -> 874.56881 | V10: =+Base!Y8 -> 0.0059903111 | X10: =+Base!N8 -> 1800 | Y10: =+U10/X10 -> 0.48587156 | Z10: =+P10-Base!O8 -> -0.00426834 | AA10: =+Base!U8 -> 6.109894 | AB10: =+Base!AL8*100 -> 39.962091 | AC10: =+Base!AM8*100 -> 42.110488 | AD10: =+Base!AG8 -> Rio Viejo 1123, Torre A, Piso 4, Departamento 407 A | AE10: 4103 | AF10: =+Base!AI8 -> Diguillín
A11: =+Base!A9 -> 8 | B11: =+Base!B9 -> 202401310046A033 | C11: =+Base!F9 -> Acuña | D11: =+Base!G9 -> Mesías | E11: =+Base!H9 -> Kevin Joel | F11: =+Base!D9 -> 16666807 | G11: =+Base!E9 -> 7 | H11: MHE | I11: =+Base!T9 -> 1345.07 | J11: =+Base!M9 -> 700 | K11: =+L11-J11-I11 -> 279.93 | L11: =+Base!L9 -> 2325 | M11: 0 | N11: =+Base!Q9 -> 144 | O11: =+Base!R9+1 -> 6 | P11: =+XIRR('Tabla desarrollo FX'!B10:MY10,'Tabla desarrollo FX'!$B$1:$MY$1) -> 0.073835269 | Q11: =+Base!AA9 -> 45514 | R11: =+Base!AD9 -> 49715 | S11: =S10 -> 45361 | T11: =+NPV(V11,'Tabla desarrollo FX'!D10:MY10) -> 1380.7573 | U11: =+Base!AF9 -> 1377.8831 | V11: =+Base!Y9 -> 0.0059903111 | X11: =+Base!N9 -> 2600 | Y11: =+U11/X11 -> 0.52995503 | Z11: =+P11-Base!O9 -> -0.0044647314 | AA11: =+Base!U9 -> 15.019052 | AB11: =+Base!AL9*100 -> 37.834186 | AC11: =+Base!AM9*100 -> 40.010103 | AD11: =+Base!AG9 -> Pasaje Copiapó Norte 071, Mz B, Lote 50 | AE11: 4103 | AF11: =+Base!AI9 -> Maipo
A12: =+Base!A10 -> 9 | B12: =+Base!B10 -> 202401310053A033 | C12: =+Base!F10 -> Valdes | D12: =+Base!G10 -> Molina | E12: =+Base!H10 -> Isabel Damari | F12: =+Base!D10 -> 14336994 | G12: =+Base!E10 -> 3 | H12: MHE | I12: =+Base!T10 -> 895 | J12: =+Base!M10 -> 750 | K12: =+L12-J12-I12 -> 80 | L12: =+Base!L10 -> 1725 | M12: 0 | N12: =+Base!Q10 -> 312 | O12: =+Base!R10+1 -> 6 | P12: =+XIRR('Tabla desarrollo FX'!B11:MY11,'Tabla desarrollo FX'!$B$1:$MY$1) -> 0.074012646 | Q12: =+Base!AA10 -> 45514 | R12: =+Base!AD10 -> 54829 | S12: =S11 -> 45361 | T12: =+NPV(V12,'Tabla desarrollo FX'!D11:MY11) -> 932.57912 | U12: =+Base!AF10 -> 930.57378 | V12: =+Base!Y10 -> 0.0059903111 | X12: =+Base!N10 -> 1725 | Y12: =+U12/X12 -> 0.53946306 | Z12: =+P12-Base!O10 -> -0.0042873539 | AA12: =+Base!U10 -> 6.810055 | AB12: =+Base!AL10*100 -> 23.19673 | AC12: =+Base!AM10*100 -> 25.290877 | AD12: =+Base!AG10 -> Pasaje Juan Vercellino Reginato 987, Mz E, Lote 9 | AE12: 4103 | AF12: =+Base!AI10 -> Cachapoal
A13: =+Base!A11 -> 10 | B13: =+Base!B11 -> 202401310054A033 | C13: =+Base!F11 -> Gonzalez | D13: =+Base!G11 -> Jaque | E13: =+Base!H11 -> Tabita Del Pilar | F13: =+Base!D11 -> 19580720 | G13: =+Base!E11 -> 5 | H13: MHE | I13: =+Base!T11 -> 895 | J13: =+Base!M11 -> 750 | K13: =+L13-J13-I13 -> 80 | L13: =+Base!L11 -> 1725 | M13: 0 | N13: =+Base!Q11 -> 228 | O13: =+Base!R11+1 -> 6 | P13: =+XIRR('Tabla desarrollo FX'!B12:MY12,'Tabla desarrollo FX'!$B$1:$MY$1) -> 0.073957667 | Q13: =+Base!AA11 -> 45514 | R13: =+Base!AD11 -> 52272 | S13: =S12 -> 45361 | T13: =+NPV(V13,'Tabla desarrollo FX'!D12:MY12) -> 926.49862 | U13: =+Base!AF11 -> 924.16029 | V13: =+Base!Y11 -> 0.0059903111 | X13: =+Base!N11 -> 1725 | Y13: =+U13/X13 -> 0.5357451 | Z13: =+P13-Base!O11 -> -0.0043423332 | AA13: =+Base!U11 -> 7.722955 | AB13: =+Base!AL11*100 -> 21.381348 | AC13: =+Base!AM11*100 -> 24.493721 | AD13: =+Base!AG11 -> Pasaje Elena Sanhueza Fajardo 794, Mz C, Lote 1 | AE13: 4103 | AF13: =+Base!AI11 -> Cachapoal
A14: =+Base!A12 -> 11 | B14: =+Base!B12 -> 202401310063A033 | C14: =+Base!F12 -> Ormeno | D14: =+Base!G12 -> Salazar | E14: =+Base!H12 -> Gino Rexner | F14: =+Base!D12 -> 14349421 | G14: =+Base!E12 -> 7 | H14: MHE | I14: =+Base!T12 -> 1595 | J14: =+Base!M12 -> 525 | K14: =+L14-J14-I14 -> 80 | L14: =+Base!L12 -> 2200 | M14: 0 | N14: =+Base!Q12 -> 360 | O14: =+Base!R12+1 -> 6 | P14: =+XIRR('Tabla desarrollo FX'!B13:MY13,'Tabla desarrollo FX'!$B$1:$MY$1) -> 0.07403166 | Q14: =+Base!AA12 -> 45514 | R14: =+Base!AD12 -> 56290 | S14: =S13 -> 45361 | T14: =+NPV(V14,'Tabla desarrollo FX'!D13:MY13) -> 1666.9944 | U14: =+Base!AF12 -> 1663.2551 | V14: =+Base!Y12 -> 0.0059903111 | X14: =+Base!N12 -> 2325 | Y14: =+U14/X14 -> 0.71537856 | Z14: =+P14-Base!O12 -> -0.00426834 | AA14: =+Base!U12 -> 11.62117 | AB14: =+Base!AL12*100 -> 43.872737 | AC14: =+Base!AM12*100 -> 48.266432 | AD14: =+Base!AG12 -> Pasaje La Cumbre 1 2505, Mz 8, Lote 4 | AE14: 4103 | AF14: =+Base!AI12 -> Biobío
A15: =+Base!A13 -> 12 | B15: =+Base!B13 -> 202401310057A033 | C15: =+Base!F13 -> Osorio | D15: =+Base!G13 -> Briones | E15: =+Base!H13 -> Marcela Andrea | F15: =+Base!D13 -> 14337194 | G15: =+Base!E13 -> 8 | H15: MHE | I15: =+Base!T13 -> 895 | J15: =+Base!M13 -> 750 | K15: =+L15-J15-I15 -> 80 | L15: =+Base!L13 -> 1725 | M15: 0 | N15: =+Base!Q13 -> 348 | O15: =+Base!R13+1 -> 6 | P15: =+XIRR('Tabla desarrollo FX'!B14:MY14,'Tabla desarrollo FX'!$B$1:$MY$1) -> 0.07402747 | Q15: =+Base!AA13 -> 45514 | R15: =+Base!AD13 -> 55925 | S15: =S14 -> 45361 | T15: =+NPV(V15,'Tabla desarrollo FX'!D14:MY14) -> 934.72947 | U15: =+Base!AF13 -> 932.21409 | V15: =+Base!Y13 -> 0.0059903111 | X15: =+Base!N13 -> 1725 | Y15: =+U15/X15 -> 0.54041396 | Z15: =+P15-Base!O13 -> -0.0042725302 | AA15: =+Base!U13 -> 6.58362 | AB15: =+Base!AL13*100 -> 11.836401 | AC15: =+Base!AM13*100 -> 41.558002 | AD15: =+Base!AG13 -> Pasaje Raquel Labarca Urzua 759, Mz C, Lote 9 | AE15: 4103 | AF15: =+Base!AI13 -> Cachapoal
A16: =+Base!A14 -> 13 | B16: =+Base!B14 -> 202401300058A033 | C16: =+Base!F14 -> Lopez | D16: =+Base!G14 -> Lopez | E16: =+Base!H14 -> Oscar Patricio | F16: =+Base!D14 -> 14009431 | G16: =+Base!E14 -> 5 | H16: MHE | I16: =+Base!T14 -> 1620 | J16: =+Base!M14 -> 700 | K16: =+L16-J16-I16 -> 80 | L16: =+Base!L14 -> 2400 | M16: 0 | N16: =+Base!Q14 -> 360 | O16: =+Base!R14+1 -> 6 | P16: =+XIRR('Tabla desarrollo FX'!B15:MY15,'Tabla desarrollo FX'!$B$1:$MY$1) -> 0.07403166 | Q16: =+Base!AA14 -> 45514 | R16: =+Base!AD14 -> 56290 | S16: =S15 -> 45361 | T16: =+NPV(V16,'Tabla desarrollo FX'!D15:MY15) -> 1693.1228 | U16: =+Base!AF14 -> 1689.0205 | V16: =+Base!Y14 -> 0.0059903111 | X16: =+Base!N14 -> 2600 | Y16: =+U16/X16 -> 0.64962326 | Z16: =+P16-Base!O14 -> -0.00426834 | AA16: =+Base!U14 -> 11.80332 | AB16: =+Base!AL14*100 -> 37.803514 | AC16: =+Base!AM14*100 -> 39.886891 | AD16: =+Base!AG14 -> Avenida Los Héroes 1328, Mz B, Lote 9 | AE16: 4103 | AF16: =+Base!AI14 -> Maipo
... A45: =+Base!A43 -> 42 | B45: =+Base!B43 -> 202402260095A033 | C45: =+Base!F43 -> Espinoza | D45: =+Base!G43 -> Huerta | E45: =+Base!H43 -> Daniela Mackarena | F45: =+Base!D43 -> 18916005 | G45: =+Base!E43 -> 4 | H45: MHE | I45: =+Base!T43 -> 1365 | J45: =+Base!M43 -> 425 | K45: =+L45-J45-I45 -> 80 | L45: =+Base!L43 -> 1870 | M45: 21 | N45: =+Base!Q43 -> 216 | O45: =+Base!R43+1 -> 6 | P45: =+XIRR('Tabla desarrollo FX'!B44:MY44,'Tabla desarrollo FX'!$B$1:$MY$1) -> 0.071563181 | Q45: =+Base!AA43 -> 45545 | R45: =+Base!AD43 -> 51935 | S45: =S44 -> 45361 | T45: =+NPV(V45,'Tabla desarrollo FX'!D44:MY44) -> 1403.4494 | U45: =+Base!AF43 -> 1400.3211 | V45: =+Base!Y43 -> 0.0058028362 | X45: =+Base!N43 -> 2100 | Y45: =+U45/X45 -> 0.66681958 | Z45: =+P45-Base!O43 -> -0.0043368187 | AA45: =+Base!U43 -> 11.890515 | AB45: =+Base!AL43*100 -> 21.950803 | AC45: =+Base!AM43*100 -> 34.815283 | AD45: =+Base!AG43 -> San Enrique 1398, Edificio 2 | AE45: 4103 | AF45: =+Base!AI43 -> Marga Marga

Sheet Valo
U1: =+SUM(U4:U45) -> 62799.219 | V1: 1 | X1: 1
I2: Monto Crédito + Cap (UF) | P2: Tasa endoso | Q2: Fecha 1er Aporte a endosar | R2: Fecha Last Aporte | S2: Fecha Corte | U2: VPN | V2: Tasa mensual de endoso | X2: Tasacion | Y2: Precio Venta/Tasación | Z2: Tasa Endoso | AA2: Monto Dividendo | AB2: Dividendo/ Renta | AC2: Carga Financiera/ Renta
A3: Nº | B3: N° Operación | C3: Apellido paterno | D3: Apellido materno | E3: Nombres | F3: Rut | G3: DV | H3: Leasing o Mutuo | J3: Subsidio | K3: Pie | L3: Valor Vivienda | M3: Morosidad | N3: Nº Cuotas | O3: Primera cuota a endosar | T3: 45332 | U3: 45351 | W3: Saldo insoluto Teórico | AD3: Dirección de la Propiedad | AE3: Codigo Comuna | AF3: Comuna
A4: 1 | B4: 202401300028A033 | C4: Bobadilla | D4: Lopez | E4: Juan Pablo | F4: 18028529 | G4: 6 | H4: MHE | I4: 1745 | J4: 375 | K4: 80 | L4: 2200 | M4: 0 | N4: 360 | O4: 6 | P4: 0.074653056 | Q4: 45514 | R4: 56290 | S4: 45332 | T4: 1812.9051 | U4: 1819.2749 | V4: 0.0059903111 | X4: 2400 | Y4: 0.7580312 | Z4: -0.0036469437 | AA4: 12.71407 | AB4: 25.258541 | AC4: 48.488599 | AD4: Camino La Vara 02600 , Edificio 3, Piso 2, Departamento 211, Estacionamiento 61 Uso y Goce | AE4: 4103 | AF4: Maipo
A5: 2 | B5: 202401310029A033 | C5: Carrillo | D5: Alarcon | E5: Francisco Javier | F5: 17540548 | G5: 8 | H5: MHE | I5: 1760 | J5: 325 | K5: 115 | L5: 2200 | M5: 0 | N5: 360 | O5: 6 | P5: 0.074653056 | Q5: 45514 | R5: 56290 | S5: 45332 | T5: 1828.4888 | U5: 1835.0201 | V5: 0.0059903111 | X5: 2650 | Y5: 0.69246041 | Z5: -0.0036469437 | AA5: 12.82336 | AB5: 28.239147 | AC5: 48.306333 | AD5: Camino Segunda Faja Al Volcán 1260, Edificio ALLIPEN, Piso 4, Departamento 403, Estacionamiento 92 Uso y Goce | AE5: 4103 | AF5: Cautín
A6: 3 | B6: 202401310030A033 | C6: Mañan | D6: Valenzuela | E6: Vicente Tomas | F6: 18465199 | G6: 8 | H6: MHE | I6: 1485 | J6: 625 | K6: 90 | L6: 2200 | M6: 0 | N6: 216 | O6: 6 | P6: 0.074813303 | Q6: 45514 | R6: 51907 | S6: 45332 | T6: 1526.4502 | U6: 1532.1686 | V6: 0.0059903111 | X6: 2200 | Y6: 0.69644028 | Z6: -0.0034866966 | AA6: 13.15116 | AB6: 13.614764 | AC6: 27.305764 | AD6: Avenida Santa Rosa 13240, Torre 3, Piso 1, Departamento 234 | AE6: 4103 | AF6: Santiago
A7: 4 | B7: 202401310034A033 | C7: Jelves | D7: Sanchez | E7: Sebastian Andres | F7: 15365153 | G7: 1 | H7: MHE | I7: 1506.34 | J7: 700 | K7: 193.66 | L7: 2400 | M7: 0 | N7: 360 | O7: 6 | P7: 0.074653056 | Q7: 45514 | R7: 56290 | S7: 45332 | T7: 1564.9579 | U7: 1571.6464 | V7: 0.0059903111 | X7: 2600 | Y7: 0.60447938 | Z7: -0.0036469437 | AA7: 10.975193 | AB7: 40.079904 | AC7: 42.389362 | AD7: Calle Miguel Campino 647, Mz D, Lote 5 | AE7: 4103 | AF7: Maipo
A8: 5 | B8: 202401310036A033 | C8: Carvajal | D8: Guajardo | E8: Danahe Estefani | F8: 18187808 | G8: 8 | H8: MHE | I8: 1285 | J8: 700 | K8: 80 | L8: 2065 | M8: 0 | N8: 360 | O8: 6 | P8: 0.074653056 | Q8: 45514 | R8: 56290 | S8: 45332 | T8: 1335.0046 | U8: 1339.7655 | V8: 0.0059903111 | X8: 2440 | Y8: 0.5490842 | Z8: -0.0036469437 | AA8: 9.36251 | AB8: 37.717378 | AC8: 39.792269 | AD8: Calle Del Toro 658, Mz D, Lote 33 | AE8: 4103 | AF8: Maipo
A9: 6 | B9: 202401250039A033 | C9: Acevedo | D9: Monje | E9: Barbara Viviana | F9: 18245649 | G9: 7 | H9: MHE | I9: 905.13 | J9: 450 | K9: 44.87 | L9: 1400 | M9: 0 | N9: 180 | O9: 6 | P9: 0.074896434 | Q9: 45514 | R9: 50811 | S9: 45332 | T9: 927.1653 | U9: 931.14903 | V9: 0.0059903111 | X9: 1400 | Y9: 0.66510645 | Z9: -0.0034035661 | AA9: 8.825923 | AB9: 41.557874 | AC9: 42.81181 | AD9: Camino La Vara 02600, Torre 2, Piso 1, Departamento 101 | AE9: 4103 | AF9: Maipo
A10: 7 | B10: 202401310041A033 | C10: Palma | D10: Ponce | E10: Carola Del Carmen | F10: 15162947 | G10: 4 | H10: MHE | I10: 838.58 | J10: 500 | K10: 61.42 | L10: 1400 | M10: 0 | N10: 360 | O10: 6 | P10: 0.074653056 | Q10: 45514 | R10: 56290 | S10: 45332 | T10: 871.21262 | U10: 874.56881 | V10: 0.0059903111 | X10: 1800 | Y10: 0.48587156 | Z10: -0.0036469437 | AA10: 6.109894 | AB10: 39.962091 | AC10: 42.110488 | AD10: Rio Viejo 1123, Torre A, Piso 4, Departamento 407 A | AE10: 4103 | AF10: Diguillín
A11: 8 | B11: 202401310046A033 | C11: Acuña | D11: Mesías | E11: Kevin Joel | F11: 16666807 | G11: 7 | H11: MHE | I11: 1345.07 | J11: 700 | K11: 279.93 | L11: 2325 | M11: 0 | N11: 144 | O11: 6 | P11: 0.075022426 | Q11: 45514 | R11: 49715 | S11: 45332 | T11: 1372.5354 | U11: 1377.8831 | V11: 0.0059903111 | X11: 2600 | Y11: 0.52995503 | Z11: -0.0032775738 | AA11: 15.019052 | AB11: 37.834186 | AC11: 40.010103 | AD11: Pasaje Copiapó Norte 071, Mz B, Lote 50 | AE11: 4103 | AF11: Maipo
A12: 9 | B12: 202401310053A033 | C12: Valdes | D12: Molina | E12: Isabel Damari | F12: 14336994 | G12: 3 | H12: MHE | I12: 895 | J12: 750 | K12: 80 | L12: 1725 | M12: 0 | N12: 312 | O12: 6 | P12: 0.074688664 | Q12: 45514 | R12: 54829 | S12: 45332 | T12: 927.02595 | U12: 930.57378 | V12: 0.0059903111 | X12: 1725 | Y12: 0.53946306 | Z12: -0.0036113359 | AA12: 6.810055 | AB12: 23.19673 | AC12: 25.290877 | AD12: Pasaje Juan Vercellino Reginato 987, Mz E, Lote 9 | AE12: 4103 | AF12: Cachapoal
A13: 10 | B13: 202401310054A033 | C13: Gonzalez | D13: Jaque | E13: Tabita Del Pilar | F13: 19580720 | G13: 5 | H13: MHE | I13: 895 | J13: 750 | K13: 80 | L13: 1725 | M13: 0 | N13: 228 | O13: 6 | P13: 0.074791661 | Q13: 45514 | R13: 52272 | S13: 45332 | T13: 920.98165 | U13: 924.16029 | V13: 0.0059903111 | X13: 1725 | Y13: 0.5357451 | Z13: -0.0035083391 | AA13: 7.722955 | AB13: 21.381348 | AC13: 24.493721 | AD13: Pasaje Elena Sanhueza Fajardo 794, Mz C, Lote 1 | AE13: 4103 | AF13: Cachapoal
A14: 11 | B14: 202401310063A033 | C14: Ormeno | D14: Salazar | E14: Gino Rexner | F14: 14349421 | G14: 7 | H14: MHE | I14: 1595 | J14: 525 | K14: 80 | L14: 2200 | M14: 0 | N14: 360 | O14: 6 | P14: 0.074653056 | Q14: 45514 | R14: 56290 | S14: 45332 | T14: 1657.068 | U14: 1663.2551 | V14: 0.0059903111 | X14: 2325 | Y14: 0.71537856 | Z14: -0.0036469437 | AA14: 11.62117 | AB14: 43.872737 | AC14: 48.266432 | AD14: Pasaje La Cumbre 1 2505, Mz 8, Lote 4 | AE14: 4103 | AF14: Biobío
A15: 12 | B15: 202401310057A033 | C15: Osorio | D15: Briones | E15: Marcela Andrea | F15: 14337194 | G15: 8 | H15: MHE | I15: 895 | J15: 750 | K15: 80 | L15: 1725 | M15: 0 | N15: 348 | O15: 6 | P15: 0.074661008 | Q15: 45514 | R15: 55925 | S15: 45332 | T15: 929.16349 | U15: 932.21409 | V15: 0.0059903111 | X15: 1725 | Y15: 0.54041396 | Z15: -0.0036389925 | AA15: 6.58362 | AB15: 11.836401 | AC15: 41.558002 | AD15: Pasaje Raquel Labarca Urzua 759, Mz C, Lote 9 | AE15: 4103 | AF15: Cachapoal
... A45: 42 | B45: 202402260095A033 | C45: Espinoza | D45: Huerta | E45: Daniela Mackarena | F45: 18916005 | G45: 4 | H45: MHE | I45: 1365 | J45: 425 | K45: 80 | L45: 1870 | M45: 21 | N45: 216 | O45: 6 | P45: 0.072386304 | Q45: 45545 | R45: 51935 | S45: 45332 | T45: 1395.3524 | U45: 1400.3211 | V45: 0.0058028362 | X45: 2100 | Y45: 0.66681958 | Z45: -0.0035136965 | AA45: 11.890515 | AB45: 21.950803 | AC45: 34.815283 | AD45: San Enrique 1398, Edificio 2 | AE45: 4103 | AF45: Marga Marga

Sheet Tabla desarrollo FX
B1: =+'Valo FX'!U3 -> 45351 | C1: ='Valo FX'!T3 -> 45361 | D1: =EDATE(C1,1) -> 45392 | E1: =EDATE(D1,1) -> 45422 | F1: =EDATE(E1,1) -> 45453 | G1: =EDATE(F1,1) -> 45483 | H1: =EDATE(G1,1) -> 45514 | I1: =EDATE(H1,1) -> 45545 | J1: =EDATE(I1,1) -> 45575 | K1: =EDATE(J1,1) -> 45606 | ... MY1: =EDATE(MX1,1) -> 56318
A2: Nº | B2: Primera cuota a endosar | C2: 1 | D2: =C2+1 -> 2 | E2: =D2+1 -> 3 | F2: =E2+1 -> 4 | G2: =F2+1 -> 5 | H2: =G2+1 -> 6 | I2: =H2+1 -> 7 | J2: =I2+1 -> 8 | K2: =J2+1 -> 9 | ... MY2: =MX2+1 -> 361
A3: =+'Valo FX'!A4 -> 1 | B3: =-'Valo FX'!T4 -> -1823.765 | C3: =IF(C$1<INDEX('Valo FX'!$Q:$Q,MATCH($A3,'Valo FX'!$A:$A,0)),0,IF(C$1<INDEX('Valo FX'!$R:$R,MATCH($A3,'Valo FX'!$A:$A,0)),INDEX(Base!$U:$U,MATCH($A3,Base!$A:$A,0)),IF(C$1=INDEX('Valo FX'!$R:$R,MATCH($A3,'Valo FX'!$A:$A,0)),INDEX(Base!$V:$V,MATCH($A3,Base!$A:$A,0)),0))) -> 0 | D3: =IF(D$1<INDEX('Valo FX'!$Q:$Q,MATCH($A3,'Valo FX'!$A:$A,0)),0,IF(D$1<INDEX('Valo FX'!$R:$R,MATCH($A3,'Valo FX'!$A:$A,0)),INDEX(Base!$U:$U,MATCH($A3,Base!$A:$A,0)),IF(D$1=INDEX('Valo FX'!$R:$R,MATCH($A3,'Valo FX'!$A:$A,0)),INDEX(Base!$V:$V,MATCH($A3,Base!$A:$A,0)),0))) -> 0 | E3: =IF(E$1<INDEX('Valo FX'!$Q:$Q,MATCH($A3,'Valo FX'!$A:$A,0)),0,IF(E$1<INDEX('Valo FX'!$R:$R,MATCH($A3,'Valo FX'!$A:$A,0)),INDEX(Base!$U:$U,MATCH($A3,Base!$A:$A,0)),IF(E$1=INDEX('Valo FX'!$R:$R,MATCH($A3,'Valo FX'!$A:$A,0)),INDEX(Base!$V:$V,MATCH($A3,Base!$A:$A,0)),0))) -> 0 | F3: =IF(F$1<INDEX('Valo FX'!$Q:$Q,MATCH($A3,'Valo FX'!$A:$A,0)),0,IF(F$1<INDEX('Valo FX'!$R:$R,MATCH($A3,'Valo FX'!$A:$A,0)),INDEX(Base!$U:$U,MATCH($A3,Base!$A:$A,0)),IF(F$1=INDEX('Valo FX'!$R:$R,MATCH($A3,'Valo FX'!$A:$A,0)),INDEX(Base!$V:$V,MATCH($A3,Base!$A:$A,0)),0))) -> 0 | G3: =IF(G$1<INDEX('Valo FX'!$Q:$Q,MATCH($A3,'Valo FX'!$A:$A,0)),0,IF(G$1<INDEX('Valo FX'!$R:$R,MATCH($A3,'Valo FX'!$A:$A,0)),INDEX(Base!$U:$U,MATCH($A3,Base!$A:$A,0)),IF(G$1=INDEX('Valo FX'!$R:$R,MATCH($A3,'Valo FX'!$A:$A,0)),INDEX(Base!$V:$V,MATCH($A3,Base!$A:$A,0)),0))) -> 0 | H3: =IF(H$1<INDEX('Valo FX'!$Q:$Q,MATCH($A3,'Valo FX'!$A:$A,0)),0,IF(H$1<INDEX('Valo FX'!$R:$R,MATCH($A3,'Valo FX'!$A:$A,0)),INDEX(Base!$U:$U,MATCH($A3,Base!$A:$A,0)),IF(H$1=INDEX('Valo FX'!$R:$R,MATCH($A3,'Valo FX'!$A:$A,0)),INDEX(Base!$V:$V,MATCH($A3,Base!$A:$A,0)),0))) -> 12.71407 | I3: =IF(I$1<INDEX('Valo FX'!$Q:$Q,MATCH($A3,'Valo FX'!$A:$A,0)),0,IF(I$1<INDEX('Valo FX'!$R:$R,MATCH($A3,'Valo FX'!$A:$A,0)),INDEX(Base!$U:$U,MATCH($A3,Base!$A:$A,0)),IF(I$1=INDEX('Valo FX'!$R:$R,MATCH($A3,'Valo FX'!$A:$A,0)),INDEX(Base!$V:$V,MATCH($A3,Base!$A:$A,0)),0))) -> 12.71407 | J3: =IF(J$1<INDEX('Valo FX'!$Q:$Q,MATCH($A3,'Valo FX'!$A:$A,0)),0,IF(J$1<INDEX('Valo FX'!$R:$R,MATCH($A3,'Valo FX'!$A:$A,0)),INDEX(Base!$U:$U,MATCH($A3,Base!$A:$A,0)),IF(J$1=INDEX('Valo FX'!$R:$R,MATCH($A3,'Valo FX'!$A:$A,0)),INDEX(Base!$V:$V,MATCH($A3,Base!$A:$A,0)),0))) -> 12.71407 | ... MY3: =IF(MY$1<INDEX('Valo FX'!$Q:$Q,MATCH($A3,'Valo FX'!$A:$A,0)),0,IF(MY$1<INDEX('Valo FX'!$R:$R,MATCH($A3,'Valo FX'!$A:$A,0)),INDEX(Base!$U:$U,MATCH($A3,Base!$A:$A,0)),IF(MY$1=INDEX('Valo FX'!$R:$R,MATCH($A3,'Valo FX'!$A:$A,0)),INDEX(Base!$V:$V,MATCH($A3,Base!$A:$A,0)),0))) -> 0
A4: =+'Valo FX'!A5 -> 2 | B4: =-'Valo FX'!T5 -> -1839.4421 | C4: =IF(C$1<INDEX('Valo FX'!$Q:$Q,MATCH($A4,'Valo FX'!$A:$A,0)),0,IF(C$1<INDEX('Valo FX'!$R:$R,MATCH($A4,'Valo FX'!$A:$A,0)),INDEX(Base!$U:$U,MATCH($A4,Base!$A:$A,0)),IF(C$1=INDEX('Valo FX'!$R:$R,MATCH($A4,'Valo FX'!$A:$A,0)),INDEX(Base!$V:$V,MATCH($A4,Base!$A:$A,0)),0))) -> 0 | D4: =IF(D$1<INDEX('Valo FX'!$Q:$Q,MATCH($A4,'Valo FX'!$A:$A,0)),0,IF(D$1<INDEX('Valo FX'!$R:$R,MATCH($A4,'Valo FX'!$A:$A,0)),INDEX(Base!$U:$U,MATCH($A4,Base!$A:$A,0)),IF(D$1=INDEX('Valo FX'!$R:$R,MATCH($A4,'Valo FX'!$A:$A,0)),INDEX(Base!$V:$V,MATCH($A4,Base!$A:$A,0)),0))) -> 0 | E4: =IF(E$1<INDEX('Valo FX'!$Q:$Q,MATCH($A4,'Valo FX'!$A:$A,0)),0,IF(E$1<INDEX('Valo FX'!$R:$R,MATCH($A4,'Valo FX'!$A:$A,0)),INDEX(Base!$U:$U,MATCH($A4,Base!$A:$A,0)),IF(E$1=INDEX('Valo FX'!$R:$R,MATCH($A4,'Valo FX'!$A:$A,0)),INDEX(Base!$V:$V,MATCH($A4,Base!$A:$A,0)),0))) -> 0 | F4: =IF(F$1<INDEX('Valo FX'!$Q:$Q,MATCH($A4,'Valo FX'!$A:$A,0)),0,IF(F$1<INDEX('Valo FX'!$R:$R,MATCH($A4,'Valo FX'!$A:$A,0)),INDEX(Base!$U:$U,MATCH($A4,Base!$A:$A,0)),IF(F$1=INDEX('Valo FX'!$R:$R,MATCH($A4,'Valo FX'!$A:$A,0)),INDEX(Base!$V:$V,MATCH($A4,Base!$A:$A,0)),0))) -> 0 | G4: =IF(G$1<INDEX('Valo FX'!$Q:$Q,MATCH($A4,'Valo FX'!$A:$A,0)),0,IF(G$1<INDEX('Valo FX'!$R:$R,MATCH($A4,'Valo FX'!$A:$A,0)),INDEX(Base!$U:$U,MATCH($A4,Base!$A:$A,0)),IF(G$1=INDEX('Valo FX'!$R:$R,MATCH($A4,'Valo FX'!$A:$A,0)),INDEX(Base!$V:$V,MATCH($A4,Base!$A:$A,0)),0))) -> 0 | H4: =IF(H$1<INDEX('Valo FX'!$Q:$Q,MATCH($A4,'Valo FX'!$A:$A,0)),0,IF(H$1<INDEX('Valo FX'!$R:$R,MATCH($A4,'Valo FX'!$A:$A,0)),INDEX(Base!$U:$U,MATCH($A4,Base!$A:$A,0)),IF(H$1=INDEX('Valo FX'!$R:$R,MATCH($A4,'Valo FX'!$A:$A,0)),INDEX(Base!$V:$V,MATCH($A4,Base!$A:$A,0)),0))) -> 12.82336 | I4: =IF(I$1<INDEX('Valo FX'!$Q:$Q,MATCH($A4,'Valo FX'!$A:$A,0)),0,IF(I$1<INDEX('Valo FX'!$R:$R,MATCH($A4,'Valo FX'!$A:$A,0)),INDEX(Base!$U:$U,MATCH($A4,Base!$A:$A,0)),IF(I$1=INDEX('Valo FX'!$R:$R,MATCH($A4,'Valo FX'!$A:$A,0)),INDEX(Base!$V:$V,MATCH($A4,Base!$A:$A,0)),0))) -> 12.82336 | J4: =IF(J$1<INDEX('Valo FX'!$Q:$Q,MATCH($A4,'Valo FX'!$A:$A,0)),0,IF(J$1<INDEX('Valo FX'!$R:$R,MATCH($A4,'Valo FX'!$A:$A,0)),INDEX(Base!$U:$U,MATCH($A4,Base!$A:$A,0)),IF(J$1=INDEX('Valo FX'!$R:$R,MATCH($A4,'Valo FX'!$A:$A,0)),INDEX(Base!$V:$V,MATCH($A4,Base!$A:$A,0)),0))) -> 12.82336 | ... MY4: =IF(MY$1<INDEX('Valo FX'!$Q:$Q,MATCH($A4,'Valo FX'!$A:$A,0)),0,IF(MY$1<INDEX('Valo FX'!$R:$R,MATCH($A4,'Valo FX'!$A:$A,0)),INDEX(Base!$U:$U,MATCH($A4,Base!$A:$A,0)),IF(MY$1=INDEX('Valo FX'!$R:$R,MATCH($A4,'Valo FX'!$A:$A,0)),INDEX(Base!$V:$V,MATCH($A4,Base!$A:$A,0)),0))) -> 0
A5: =+'Valo FX'!A6 -> 3 | B5: =-'Valo FX'!T6 -> -1535.5941 | C5: =IF(C$1<INDEX('Valo FX'!$Q:$Q,MATCH($A5,'Valo FX'!$A:$A,0)),0,IF(C$1<INDEX('Valo FX'!$R:$R,MATCH($A5,'Valo FX'!$A:$A,0)),INDEX(Base!$U:$U,MATCH($A5,Base!$A:$A,0)),IF(C$1=INDEX('Valo FX'!$R:$R,MATCH($A5,'Valo FX'!$A:$A,0)),INDEX(Base!$V:$V,MATCH($A5,Base!$A:$A,0)),0))) -> 0 | D5: =IF(D$1<INDEX('Valo FX'!$Q:$Q,MATCH($A5,'Valo FX'!$A:$A,0)),0,IF(D$1<INDEX('Valo FX'!$R:$R,MATCH($A5,'Valo FX'!$A:$A,0)),INDEX(Base!$U:$U,MATCH($A5,Base!$A:$A,0)),IF(D$1=INDEX('Valo FX'!$R:$R,MATCH($A5,'Valo FX'!$A:$A,0)),INDEX(Base!$V:$V,MATCH($A5,Base!$A:$A,0)),0))) -> 0 | E5: =IF(E$1<INDEX('Valo FX'!$Q:$Q,MATCH($A5,'Valo FX'!$A:$A,0)),0,IF(E$1<INDEX('Valo FX'!$R:$R,MATCH($A5,'Valo FX'!$A:$A,0)),INDEX(Base!$U:$U,MATCH($A5,Base!$A:$A,0)),IF(E$1=INDEX('Valo FX'!$R:$R,MATCH($A5,'Valo FX'!$A:$A,0)),INDEX(Base!$V:$V,MATCH($A5,Base!$A:$A,0)),0))) -> 0 | F5: =IF(F$1<INDEX('Valo FX'!$Q:$Q,MATCH($A5,'Valo FX'!$A:$A,0)),0,IF(F$1<INDEX('Valo FX'!$R:$R,MATCH($A5,'Valo FX'!$A:$A,0)),INDEX(Base!$U:$U,MATCH($A5,Base!$A:$A,0)),IF(F$1=INDEX('Valo FX'!$R:$R,MATCH($A5,'Valo FX'!$A:$A,0)),INDEX(Base!$V:$V,MATCH($A5,Base!$A:$A,0)),0))) -> 0 | G5: =IF(G$1<INDEX('Valo FX'!$Q:$Q,MATCH($A5,'Valo FX'!$A:$A,0)),0,IF(G$1<INDEX('Valo FX'!$R:$R,MATCH($A5,'Valo FX'!$A:$A,0)),INDEX(Base!$U:$U,MATCH($A5,Base!$A:$A,0)),IF(G$1=INDEX('Valo FX'!$R:$R,MATCH($A5,'Valo FX'!$A:$A,0)),INDEX(Base!$V:$V,MATCH($A5,Base!$A:$A,0)),0))) -> 0 | H5: =IF(H$1<INDEX('Valo FX'!$Q:$Q,MATCH($A5,'Valo FX'!$A:$A,0)),0,IF(H$1<INDEX('Valo FX'!$R:$R,MATCH($A5,'Valo FX'!$A:$A,0)),INDEX(Base!$U:$U,MATCH($A5,Base!$A:$A,0)),IF(H$1=INDEX('Valo FX'!$R:$R,MATCH($A5,'Valo FX'!$A:$A,0)),INDEX(Base!$V:$V,MATCH($A5,Base!$A:$A,0)),0))) -> 13.15116 | I5: =IF(I$1<INDEX('Valo FX'!$Q:$Q,MATCH($A5,'Valo FX'!$A:$A,0)),0,IF(I$1<INDEX('Valo FX'!$R:$R,MATCH($A5,'Valo FX'!$A:$A,0)),INDEX(Base!$U:$U,MATCH($A5,Base!$A:$A,0)),IF(I$1=INDEX('Valo FX'!$R:$R,MATCH($A5,'Valo FX'!$A:$A,0)),INDEX(Base!$V:$V,MATCH($A5,Base!$A:$A,0)),0))) -> 13.15116 | J5: =IF(J$1<INDEX('Valo FX'!$Q:$Q,MATCH($A5,'Valo FX'!$A:$A,0)),0,IF(J$1<INDEX('Valo FX'!$R:$R,MATCH($A5,'Valo FX'!$A:$A,0)),INDEX(Base!$U:$U,MATCH($A5,Base!$A:$A,0)),IF(J$1=INDEX('Valo FX'!$R:$R,MATCH($A5,'Valo FX'!$A:$A,0)),INDEX(Base!$V:$V,MATCH($A5,Base!$A:$A,0)),0))) -> 13.15116 | ... MY5: =IF(MY$1<INDEX('Valo FX'!$Q:$Q,MATCH($A5,'Valo FX'!$A:$A,0)),0,IF(MY$1<INDEX('Valo FX'!$R:$R,MATCH($A5,'Valo FX'!$A:$A,0)),INDEX(Base!$U:$U,MATCH($A5,Base!$A:$A,0)),IF(MY$1=INDEX('Valo FX'!$R:$R,MATCH($A5,'Valo FX'!$A:$A,0)),INDEX(Base!$V:$V,MATCH($A5,Base!$A:$A,0)),0))) -> 0
A6: =+'Valo FX'!A7 -> 4 | B6: =-'Valo FX'!T7 -> -1574.3324 | C6: =IF(C$1<INDEX('Valo FX'!$Q:$Q,MATCH($A6,'Valo FX'!$A:$A,0)),0,IF(C$1<INDEX('Valo FX'!$R:$R,MATCH($A6,'Valo FX'!$A:$A,0)),INDEX(Base!$U:$U,MATCH($A6,Base!$A:$A,0)),IF(C$1=INDEX('Valo FX'!$R:$R,MATCH($A6,'Valo FX'!$A:$A,0)),INDEX(Base!$V:$V,MATCH($A6,Base!$A:$A,0)),0))) -> 0 | D6: =IF(D$1<INDEX('Valo FX'!$Q:$Q,MATCH($A6,'Valo FX'!$A:$A,0)),0,IF(D$1<INDEX('Valo FX'!$R:$R,MATCH($A6,'Valo FX'!$A:$A,0)),INDEX(Base!$U:$U,MATCH($A6,Base!$A:$A,0)),IF(D$1=INDEX('Valo FX'!$R:$R,MATCH($A6,'Valo FX'!$A:$A,0)),INDEX(Base!$V:$V,MATCH($A6,Base!$A:$A,0)),0))) -> 0 | E6: =IF(E$1<INDEX('Valo FX'!$Q:$Q,MATCH($A6,'Valo FX'!$A:$A,0)),0,IF(E$1<INDEX('Valo FX'!$R:$R,MATCH($A6,'Valo FX'!$A:$A,0)),INDEX(Base!$U:$U,MATCH($A6,Base!$A:$A,0)),IF(E$1=INDEX('Valo FX'!$R:$R,MATCH($A6,'Valo FX'!$A:$A,0)),INDEX(Base!$V:$V,MATCH($A6,Base!$A:$A,0)),0))) -> 0 | F6: =IF(F$1<INDEX('Valo FX'!$Q:$Q,MATCH($A6,'Valo FX'!$A:$A,0)),0,IF(F$1<INDEX('Valo FX'!$R:$R,MATCH($A6,'Valo FX'!$A:$A,0)),INDEX(Base!$U:$U,MATCH($A6,Base!$A:$A,0)),IF(F$1=INDEX('Valo FX'!$R:$R,MATCH($A6,'Valo FX'!$A:$A,0)),INDEX(Base!$V:$V,MATCH($A6,Base!$A:$A,0)),0))) -> 0 | G6: =IF(G$1<INDEX('Valo FX'!$Q:$Q,MATCH($A6,'Valo FX'!$A:$A,0)),0,IF(G$1<INDEX('Valo FX'!$R:$R,MATCH($A6,'Valo FX'!$A:$A,0)),INDEX(Base!$U:$U,MATCH($A6,Base!$A:$A,0)),IF(G$1=INDEX('Valo FX'!$R:$R,MATCH($A6,'Valo FX'!$A:$A,0)),INDEX(Base!$V:$V,MATCH($A6,Base!$A:$A,0)),0))) -> 0 | H6: =IF(H$1<INDEX('Valo FX'!$Q:$Q,MATCH($A6,'Valo FX'!$A:$A,0)),0,IF(H$1<INDEX('Valo FX'!$R:$R,MATCH($A6,'Valo FX'!$A:$A,0)),INDEX(Base!$U:$U,MATCH($A6,Base!$A:$A,0)),IF(H$1=INDEX('Valo FX'!$R:$R,MATCH($A6,'Valo FX'!$A:$A,0)),INDEX(Base!$V:$V,MATCH($A6,Base!$A:$A,0)),0))) -> 10.975193 | I6: =IF(I$1<INDEX('Valo FX'!$Q:$Q,MATCH($A6,'Valo FX'!$A:$A,0)),0,IF(I$1<INDEX('Valo FX'!$R:$R,MATCH($A6,'Valo FX'!$A:$A,0)),INDEX(Base!$U:$U,MATCH($A6,Base!$A:$A,0)),IF(I$1=INDEX('Valo FX'!$R:$R,MATCH($A6,'Valo FX'!$A:$A,0)),INDEX(Base!$V:$V,MATCH($A6,Base!$A:$A,0)),0))) -> 10.975193 | J6: =IF(J$1<INDEX('Valo FX'!$Q:$Q,MATCH($A6,'Valo FX'!$A:$A,0)),0,IF(J$1<INDEX('Valo FX'!$R:$R,MATCH($A6,'Valo FX'!$A:$A,0)),INDEX(Base!$U:$U,MATCH($A6,Base!$A:$A,0)),IF(J$1=INDEX('Valo FX'!$R:$R,MATCH($A6,'Valo FX'!$A:$A,0)),INDEX(Base!$V:$V,MATCH($A6,Base!$A:$A,0)),0))) -> 10.975193 | ... MY6: =IF(MY$1<INDEX('Valo FX'!$Q:$Q,MATCH($A6,'Valo FX'!$A:$A,0)),0,IF(MY$1<INDEX('Valo FX'!$R:$R,MATCH($A6,'Valo FX'!$A:$A,0)),INDEX(Base!$U:$U,MATCH($A6,Base!$A:$A,0)),IF(MY$1=INDEX('Valo FX'!$R:$R,MATCH($A6,'Valo FX'!$A:$A,0)),INDEX(Base!$V:$V,MATCH($A6,Base!$A:$A,0)),0))) -> 0
A7: =+'Valo FX'!A8 -> 5 | B7: =-'Valo FX'!T8 -> -1343.0017 | C7: =IF(C$1<INDEX('Valo FX'!$Q:$Q,MATCH($A7,'Valo FX'!$A:$A,0)),0,IF(C$1<INDEX('Valo FX'!$R:$R,MATCH($A7,'Valo FX'!$A:$A,0)),INDEX(Base!$U:$U,MATCH($A7,Base!$A:$A,0)),IF(C$1=INDEX('Valo FX'!$R:$R,MATCH($A7,'Valo FX'!$A:$A,0)),INDEX(Base!$V:$V,MATCH($A7,Base!$A:$A,0)),0))) -> 0 | D7: =IF(D$1<INDEX('Valo FX'!$Q:$Q,MATCH($A7,'Valo FX'!$A:$A,0)),0,IF(D$1<INDEX('Valo FX'!$R:$R,MATCH($A7,'Valo FX'!$A:$A,0)),INDEX(Base!$U:$U,MATCH($A7,Base!$A:$A,0)),IF(D$1=INDEX('Valo FX'!$R:$R,MATCH($A7,'Valo FX'!$A:$A,0)),INDEX(Base!$V:$V,MATCH($A7,Base!$A:$A,0)),0))) -> 0 | E7: =IF(E$1<INDEX('Valo FX'!$Q:$Q,MATCH($A7,'Valo FX'!$A:$A,0)),0,IF(E$1<INDEX('Valo FX'!$R:$R,MATCH($A7,'Valo FX'!$A:$A,0)),INDEX(Base!$U:$U,MATCH($A7,Base!$A:$A,0)),IF(E$1=INDEX('Valo FX'!$R:$R,MATCH($A7,'Valo FX'!$A:$A,0)),INDEX(Base!$V:$V,MATCH($A7,Base!$A:$A,0)),0))) -> 0 | F7: =IF(F$1<INDEX('Valo FX'!$Q:$Q,MATCH($A7,'Valo FX'!$A:$A,0)),0,IF(F$1<INDEX('Valo FX'!$R:$R,MATCH($A7,'Valo FX'!$A:$A,0)),INDEX(Base!$U:$U,MATCH($A7,Base!$A:$A,0)),IF(F$1=INDEX('Valo FX'!$R:$R,MATCH($A7,'Valo FX'!$A:$A,0)),INDEX(Base!$V:$V,MATCH($A7,Base!$A:$A,0)),0))) -> 0 | G7: =IF(G$1<INDEX('Valo FX'!$Q:$Q,MATCH($A7,'Valo FX'!$A:$A,0)),0,IF(G$1<INDEX('Valo FX'!$R:$R,MATCH($A7,'Valo FX'!$A:$A,0)),INDEX(Base!$U:$U,MATCH($A7,Base!$A:$A,0)),IF(G$1=INDEX('Valo FX'!$R:$R,MATCH($A7,'Valo FX'!$A:$A,0)),INDEX(Base!$V:$V,MATCH($A7,Base!$A:$A,0)),0))) -> 0 | H7: =IF(H$1<INDEX('Valo FX'!$Q:$Q,MATCH($A7,'Valo FX'!$A:$A,0)),0,IF(H$1<INDEX('Valo FX'!$R:$R,MATCH($A7,'Valo FX'!$A:$A,0)),INDEX(Base!$U:$U,MATCH($A7,Base!$A:$A,0)),IF(H$1=INDEX('Valo FX'!$R:$R,MATCH($A7,'Valo FX'!$A:$A,0)),INDEX(Base!$V:$V,MATCH($A7,Base!$A:$A,0)),0))) -> 9.36251 | I7: =IF(I$1<INDEX('Valo FX'!$Q:$Q,MATCH($A7,'Valo FX'!$A:$A,0)),0,IF(I$1<INDEX('Valo FX'!$R:$R,MATCH($A7,'Valo FX'!$A:$A,0)),INDEX(Base!$U:$U,MATCH($A7,Base!$A:$A,0)),IF(I$1=INDEX('Valo FX'!$R:$R,MATCH($A7,'Valo FX'!$A:$A,0)),INDEX(Base!$V:$V,MATCH($A7,Base!$A:$A,0)),0))) -> 9.36251 | J7: =IF(J$1<INDEX('Valo FX'!$Q:$Q,MATCH($A7,'Valo FX'!$A:$A,0)),0,IF(J$1<INDEX('Valo FX'!$R:$R,MATCH($A7,'Valo FX'!$A:$A,0)),INDEX(Base!$U:$U,MATCH($A7,Base!$A:$A,0)),IF(J$1=INDEX('Valo FX'!$R:$R,MATCH($A7,'Valo FX'!$A:$A,0)),INDEX(Base!$V:$V,MATCH($A7,Base!$A:$A,0)),0))) -> 9.36251 | ... MY7: =IF(MY$1<INDEX('Valo FX'!$Q:$Q,MATCH($A7,'Valo FX'!$A:$A,0)),0,IF(MY$1<INDEX('Valo FX'!$R:$R,MATCH($A7,'Valo FX'!$A:$A,0)),INDEX(Base!$U:$U,MATCH($A7,Base!$A:$A,0)),IF(MY$1=INDEX('Valo FX'!$R:$R,MATCH($A7,'Valo FX'!$A:$A,0)),INDEX(Base!$V:$V,MATCH($A7,Base!$A:$A,0)),0))) -> 0
A8: =+'Valo FX'!A9 -> 6 | B8: =-'Valo FX'!T9 -> -932.71931 | C8: =IF(C$1<INDEX('Valo FX'!$Q:$Q,MATCH($A8,'Valo FX'!$A:$A,0)),0,IF(C$1<INDEX('Valo FX'!$R:$R,MATCH($A8,'Valo FX'!$A:$A,0)),INDEX(Base!$U:$U,MATCH($A8,Base!$A:$A,0)),IF(C$1=INDEX('Valo FX'!$R:$R,MATCH($A8,'Valo FX'!$A:$A,0)),INDEX(Base!$V:$V,MATCH($A8,Base!$A:$A,0)),0))) -> 0 | D8: =IF(D$1<INDEX('Valo FX'!$Q:$Q,MATCH($A8,'Valo FX'!$A:$A,0)),0,IF(D$1<INDEX('Valo FX'!$R:$R,MATCH($A8,'Valo FX'!$A:$A,0)),INDEX(Base!$U:$U,MATCH($A8,Base!$A:$A,0)),IF(D$1=INDEX('Valo FX'!$R:$R,MATCH($A8,'Valo FX'!$A:$A,0)),INDEX(Base!$V:$V,MATCH($A8,Base!$A:$A,0)),0))) -> 0 | E8: =IF(E$1<INDEX('Valo FX'!$Q:$Q,MATCH($A8,'Valo FX'!$A:$A,0)),0,IF(E$1<INDEX('Valo FX'!$R:$R,MATCH($A8,'Valo FX'!$A:$A,0)),INDEX(Base!$U:$U,MATCH($A8,Base!$A:$A,0)),IF(E$1=INDEX('Valo FX'!$R:$R,MATCH($A8,'Valo FX'!$A:$A,0)),INDEX(Base!$V:$V,MATCH($A8,Base!$A:$A,0)),0))) -> 0 | F8: =IF(F$1<INDEX('Valo FX'!$Q:$Q,MATCH($A8,'Valo FX'!$A:$A,0)),0,IF(F$1<INDEX('Valo FX'!$R:$R,MATCH($A8,'Valo FX'!$A:$A,0)),INDEX(Base!$U:$U,MATCH($A8,Base!$A:$A,0)),IF(F$1=INDEX('Valo FX'!$R:$R,MATCH($A8,'Valo FX'!$A:$A,0)),INDEX(Base!$V:$V,MATCH($A8,Base!$A:$A,0)),0))) -> 0 | G8: =IF(G$1<INDEX('Valo FX'!$Q:$Q,MATCH($A8,'Valo FX'!$A:$A,0)),0,IF(G$1<INDEX('Valo FX'!$R:$R,MATCH($A8,'Valo FX'!$A:$A,0)),INDEX(Base!$U:$U,MATCH($A8,Base!$A:$A,0)),IF(G$1=INDEX('Valo FX'!$R:$R,MATCH($A8,'Valo FX'!$A:$A,0)),INDEX(Base!$V:$V,MATCH($A8,Base!$A:$A,0)),0))) -> 0 | H8: =IF(H$1<INDEX('Valo FX'!$Q:$Q,MATCH($A8,'Valo FX'!$A:$A,0)),0,IF(H$1<INDEX('Valo FX'!$R:$R,MATCH($A8,'Valo FX'!$A:$A,0)),INDEX(Base!$U:$U,MATCH($A8,Base!$A:$A,0)),IF(H$1=INDEX('Valo FX'!$R:$R,MATCH($A8,'Valo FX'!$A:$A,0)),INDEX(Base!$V:$V,MATCH($A8,Base!$A:$A,0)),0))) -> 8.825923 | I8: =IF(I$1<INDEX('Valo FX'!$Q:$Q,MATCH($A8,'Valo FX'!$A:$A,0)),0,IF(I$1<INDEX('Valo FX'!$R:$R,MATCH($A8,'Valo FX'!$A:$A,0)),INDEX(Base!$U:$U,MATCH($A8,Base!$A:$A,0)),IF(I$1=INDEX('Valo FX'!$R:$R,MATCH($A8,'Valo FX'!$A:$A,0)),INDEX(Base!$V:$V,MATCH($A8,Base!$A:$A,0)),0))) -> 8.825923 | J8: =IF(J$1<INDEX('Valo FX'!$Q:$Q,MATCH($A8,'Valo FX'!$A:$A,0)),0,IF(J$1<INDEX('Valo FX'!$R:$R,MATCH($A8,'Valo FX'!$A:$A,0)),INDEX(Base!$U:$U,MATCH($A8,Base!$A:$A,0)),IF(J$1=INDEX('Valo FX'!$R:$R,MATCH($A8,'Valo FX'!$A:$A,0)),INDEX(Base!$V:$V,MATCH($A8,Base!$A:$A,0)),0))) -> 8.825923 | ... MY8: =IF(MY$1<INDEX('Valo FX'!$Q:$Q,MATCH($A8,'Valo FX'!$A:$A,0)),0,IF(MY$1<INDEX('Valo FX'!$R:$R,MATCH($A8,'Valo FX'!$A:$A,0)),INDEX(Base!$U:$U,MATCH($A8,Base!$A:$A,0)),IF(MY$1=INDEX('Valo FX'!$R:$R,MATCH($A8,'Valo FX'!$A:$A,0)),INDEX(Base!$V:$V,MATCH($A8,Base!$A:$A,0)),0))) -> 0
A9: =+'Valo FX'!A10 -> 7 | B9: =-'Valo FX'!T10 -> -876.43145 | C9: =IF(C$1<INDEX('Valo FX'!$Q:$Q,MATCH($A9,'Valo FX'!$A:$A,0)),0,IF(C$1<INDEX('Valo FX'!$R:$R,MATCH($A9,'Valo FX'!$A:$A,0)),INDEX(Base!$U:$U,MATCH($A9,Base!$A:$A,0)),IF(C$1=INDEX('Valo FX'!$R:$R,MATCH($A9,'Valo FX'!$A:$A,0)),INDEX(Base!$V:$V,MATCH($A9,Base!$A:$A,0)),0))) -> 0 | D9: =IF(D$1<INDEX('Valo FX'!$Q:$Q,MATCH($A9,'Valo FX'!$A:$A,0)),0,IF(D$1<INDEX('Valo FX'!$R:$R,MATCH($A9,'Valo FX'!$A:$A,0)),INDEX(Base!$U:$U,MATCH($A9,Base!$A:$A,0)),IF(D$1=INDEX('Valo FX'!$R:$R,MATCH($A9,'Valo FX'!$A:$A,0)),INDEX(Base!$V:$V,MATCH($A9,Base!$A:$A,0)),0))) -> 0 | E9: =IF(E$1<INDEX('Valo FX'!$Q:$Q,MATCH($A9,'Valo FX'!$A:$A,0)),0,IF(E$1<INDEX('Valo FX'!$R:$R,MATCH($A9,'Valo FX'!$A:$A,0)),INDEX(Base!$U:$U,MATCH($A9,Base!$A:$A,0)),IF(E$1=INDEX('Valo FX'!$R:$R,MATCH($A9,'Valo FX'!$A:$A,0)),INDEX(Base!$V:$V,MATCH($A9,Base!$A:$A,0)),0))) -> 0 | F9: =IF(F$1<INDEX('Valo FX'!$Q:$Q,MATCH($A9,'Valo FX'!$A:$A,0)),0,IF(F$1<INDEX('Valo FX'!$R:$R,MATCH($A9,'Valo FX'!$A:$A,0)),INDEX(Base!$U:$U,MATCH($A9,Base!$A:$A,0)),IF(F$1=INDEX('Valo FX'!$R:$R,MATCH($A9,'Valo FX'!$A:$A,0)),INDEX(Base!$V:$V,MATCH($A9,Base!$A:$A,0)),0))) -> 0 | G9: =IF(G$1<INDEX('Valo FX'!$Q:$Q,MATCH($A9,'Valo FX'!$A:$A,0)),0,IF(G$1<INDEX('Valo FX'!$R:$R,MATCH($A9,'Valo FX'!$A:$A,0)),INDEX(Base!$U:$U,MATCH($A9,Base!$A:$A,0)),IF(G$1=INDEX('Valo FX'!$R:$R,MATCH($A9,'Valo FX'!$A:$A,0)),INDEX(Base!$V:$V,MATCH($A9,Base!$A:$A,0)),0))) -> 0 | H9: =IF(H$1<INDEX('Valo FX'!$Q:$Q,MATCH($A9,'Valo FX'!$A:$A,0)),0,IF(H$1<INDEX('Valo FX'!$R:$R,MATCH($A9,'Valo FX'!$A:$A,0)),INDEX(Base!$U:$U,MATCH($A9,Base!$A:$A,0)),IF(H$1=INDEX('Valo FX'!$R:$R,MATCH($A9,'Valo FX'!$A:$A,0)),INDEX(Base!$V:$V,MATCH($A9,Base!$A:$A,0)),0))) -> 6.109894 | I9: =IF(I$1<INDEX('Valo FX'!$Q:$Q,MATCH($A9,'Valo FX'!$A:$A,0)),0,IF(I$1<INDEX('Valo FX'!$R:$R,MATCH($A9,'Valo FX'!$A:$A,0)),INDEX(Base!$U:$U,MATCH($A9,Base!$A:$A,0)),IF(I$1=INDEX('Valo FX'!$R:$R,MATCH($A9,'Valo FX'!$A:$A,0)),INDEX(Base!$V:$V,MATCH($A9,Base!$A:$A,0)),0))) -> 6.109894 | J9: =IF(J$1<INDEX('Valo FX'!$Q:$Q,MATCH($A9,'Valo FX'!$A:$A,0)),0,IF(J$1<INDEX('Valo FX'!$R:$R,MATCH($A9,'Valo FX'!$A:$A,0)),INDEX(Base!$U:$U,MATCH($A9,Base!$A:$A,0)),IF(J$1=INDEX('Valo FX'!$R:$R,MATCH($A9,'Valo FX'!$A:$A,0)),INDEX(Base!$V:$V,MATCH($A9,Base!$A:$A,0)),0))) -> 6.109894 | ... MY9: =IF(MY$1<INDEX('Valo FX'!$Q:$Q,MATCH($A9,'Valo FX'!$A:$A,0)),0,IF(MY$1<INDEX('Valo FX'!$R:$R,MATCH($A9,'Valo FX'!$A:$A,0)),INDEX(Base!$U:$U,MATCH($A9,Base!$A:$A,0)),IF(MY$1=INDEX('Valo FX'!$R:$R,MATCH($A9,'Valo FX'!$A:$A,0)),INDEX(Base!$V:$V,MATCH($A9,Base!$A:$A,0)),0))) -> 0
A10: =+'Valo FX'!A11 -> 8 | B10: =-'Valo FX'!T11 -> -1380.7573 | C10: =IF(C$1<INDEX('Valo FX'!$Q:$Q,MATCH($A10,'Valo FX'!$A:$A,0)),0,IF(C$1<INDEX('Valo FX'!$R:$R,MATCH($A10,'Valo FX'!$A:$A,0)),INDEX(Base!$U:$U,MATCH($A10,Base!$A:$A,0)),IF(C$1=INDEX('Valo FX'!$R:$R,MATCH($A10,'Valo FX'!$A:$A,0)),INDEX(Base!$V:$V,MATCH($A10,Base!$A:$A,0)),0))) -> 0 | D10: =IF(D$1<INDEX('Valo FX'!$Q:$Q,MATCH($A10,'Valo FX'!$A:$A,0)),0,IF(D$1<INDEX('Valo FX'!$R:$R,MATCH($A10,'Valo FX'!$A:$A,0)),INDEX(Base!$U:$U,MATCH($A10,Base!$A:$A,0)),IF(D$1=INDEX('Valo FX'!$R:$R,MATCH($A10,'Valo FX'!$A:$A,0)),INDEX(Base!$V:$V,MATCH($A10,Base!$A:$A,0)),0))) -> 0 | E10: =IF(E$1<INDEX('Valo FX'!$Q:$Q,MATCH($A10,'Valo FX'!$A:$A,0)),0,IF(E$1<INDEX('Valo FX'!$R:$R,MATCH($A10,'Valo FX'!$A:$A,0)),INDEX(Base!$U:$U,MATCH($A10,Base!$A:$A,0)),IF(E$1=INDEX('Valo FX'!$R:$R,MATCH($A10,'Valo FX'!$A:$A,0)),INDEX(Base!$V:$V,MATCH($A10,Base!$A:$A,0)),0))) -> 0 | F10: =IF(F$1<INDEX('Valo FX'!$Q:$Q,MATCH($A10,'Valo FX'!$A:$A,0)),0,IF(F$1<INDEX('Valo FX'!$R:$R,MATCH($A10,'Valo FX'!$A:$A,0)),INDEX(Base!$U:$U,MATCH($A10,Base!$A:$A,0)),IF(F$1=INDEX('Valo FX'!$R:$R,MATCH($A10,'Valo FX'!$A:$A,0)),INDEX(Base!$V:$V,MATCH($A10,Base!$A:$A,0)),0))) -> 0 | G10: =IF(G$1<INDEX('Valo FX'!$Q:$Q,MATCH($A10,'Valo FX'!$A:$A,0)),0,IF(G$1<INDEX('Valo FX'!$R:$R,MATCH($A10,'Valo FX'!$A:$A,0)),INDEX(Base!$U:$U,MATCH($A10,Base!$A:$A,0)),IF(G$1=INDEX('Valo FX'!$R:$R,MATCH($A10,'Valo FX'!$A:$A,0)),INDEX(Base!$V:$V,MATCH($A10,Base!$A:$A,0)),0))) -> 0 | H10: =IF(H$1<INDEX('Valo FX'!$Q:$Q,MATCH($A10,'Valo FX'!$A:$A,0)),0,IF(H$1<INDEX('Valo FX'!$R:$R,MATCH($A10,'Valo FX'!$A:$A,0)),INDEX(Base!$U:$U,MATCH($A10,Base!$A:$A,0)),IF(H$1=INDEX('Valo FX'!$R:$R,MATCH($A10,'Valo FX'!$A:$A,0)),INDEX(Base!$V:$V,MATCH($A10,Base!$A:$A,0)),0))) -> 15.019052 | I10: =IF(I$1<INDEX('Valo FX'!$Q:$Q,MATCH($A10,'Valo FX'!$A:$A,0)),0,IF(I$1<INDEX('Valo FX'!$R:$R,MATCH($A10,'Valo FX'!$A:$A,0)),INDEX(Base!$U:$U,MATCH($A10,Base!$A:$A,0)),IF(I$1=INDEX('Valo FX'!$R:$R,MATCH($A10,'Valo FX'!$A:$A,0)),INDEX(Base!$V:$V,MATCH($A10,Base!$A:$A,0)),0))) -> 15.019052 | J10: =IF(J$1<INDEX('Valo FX'!$Q:$Q,MATCH($A10,'Valo FX'!$A:$A,0)),0,IF(J$1<INDEX('Valo FX'!$R:$R,MATCH($A10,'Valo FX'!$A:$A,0)),INDEX(Base!$U:$U,MATCH($A10,Base!$A:$A,0)),IF(J$1=INDEX('Valo FX'!$R:$R,MATCH($A10,'Valo FX'!$A:$A,0)),INDEX(Base!$V:$V,MATCH($A10,Base!$A:$A,0)),0))) -> 15.019052 | ... MY10: =IF(MY$1<INDEX('Valo FX'!$Q:$Q,MATCH($A10,'Valo FX'!$A:$A,0)),0,IF(MY$1<INDEX('Valo FX'!$R:$R,MATCH($A10,'Valo FX'!$A:$A,0)),INDEX(Base!$U:$U,MATCH($A10,Base!$A:$A,0)),IF(MY$1=INDEX('Valo FX'!$R:$R,MATCH($A10,'Valo FX'!$A:$A,0)),INDEX(Base!$V:$V,MATCH($A10,Base!$A:$A,0)),0))) -> 0
